Workbook
Name \c: #N/A
Name \e: #N/A
Name \f: #N/A
Name \g: #N/A
Name \o: #N/A
Name \p: #N/A
Name \r: #N/A
Name \s: #N/A
Name _1: #REF!
Name _2: #REF!
Name _OUT2: [1]SLIP!$J$96
Name DATA: #REF!
Name PTKP: #REF!

Sheet Dept (不許動)
B1: STL 1&2 | D1: STL 3&4 | F1: GLR1 | H1: MK | J1: 2A | L1: 2B | N1: 2C | P1: GLD | S1: Dept | T1: DL/IDL | U1: Belong to | V1: HL
B2: Administration | D2: Administration | F2: ADMINISTRATION | H2: Administration | J2: Administration | L2: Administration | N2: Administration | P2: Administration | S2: Administration | AA2: Cutting
B3: Driver | D3: Driver | E3: =MATCH(D3,$S$3:$S$15,0) -> 7 | F3: Policlinic(Nurse) | G3: =MATCH(F3,$S$3:$S$16,0) -> 11 | H3: Driver | I3: =MATCH(H3,$S$3:$S$16,0) -> 7 | J3: Policlinic(Nurse) | K3: =MATCH(J3,$S$3:$S$17,0) -> 11 | L3: Policlinic(Nurse) | M3: =MATCH(L3,$S$3:$S$17,0) -> 11 | N3: Policlinic(Nurse) | O3: =MATCH(N3,$S$3:$S$20,0) -> 11 | P3: Policlinic(Nurse) | Q3: =MATCH(P3,$S$3:$S$20,0) -> 11 | S3: Security | T3: IDL | U3: IDL others | AA3: IDL Sewing
B4: Exim | D4: Exim | E4: =MATCH(D4,$S$3:$S$15,0) -> 9 | F4: Security | G4: =MATCH(F4,$S$3:$S$16,0) -> 1 | H4: Exim | I4: =MATCH(H4,$S$3:$S$16,0) -> 9 | J4: Security | K4: =MATCH(J4,$S$3:$S$17,0) -> 1 | L4: Security | M4: =MATCH(L4,$S$3:$S$17,0) -> 1 | N4: Security | O4: =MATCH(N4,$S$3:$S$20,0) -> 1 | P4: Security | Q4: =MATCH(P4,$S$3:$S$20,0) -> 1 | S4: Purchasing/EDP | T4: IDL | U4: IDL others | AA4: Embordiary
B5: Finance(Accounting/Cashier) | D5: Finance(Accounting/Cashier) | E5: =MATCH(D5,$S$3:$S$15,0) -> 4 | F5: Finance(Accounting/Cashier) | G5: =MATCH(F5,$S$3:$S$16,0) -> 4 | H5: Factory Manager | I5: =MATCH(H5,$S$3:$S$16,0) -> 3 | J5: Finance(Accounting/Cashier) | K5: =MATCH(J5,$S$3:$S$17,0) -> 4 | L5: Finance(Accounting/Cashier) | M5: =MATCH(L5,$S$3:$S$17,0) -> 4 | N5: Finance(Accounting/Cashier) | O5: =MATCH(N5,$S$3:$S$20,0) -> 4 | P5: Finance(Accounting/Cashier) | Q5: =MATCH(P5,$S$3:$S$20,0) -> 4 | S5: Factory Manager | T5: IDL | U5: IDL others | AA5: Sewing
B6: General Affair | D6: General Affair | E6: =MATCH(D6,$S$3:$S$15,0) -> 5 | F6: General Affair | G6: =MATCH(F6,$S$3:$S$16,0) -> 5 | H6: Finance(Accounting/Cashier) | I6: =MATCH(H6,$S$3:$S$16,0) -> 4 | J6: General Affair | K6: =MATCH(J6,$S$3:$S$17,0) -> 5 | L6: General Affair | M6: =MATCH(L6,$S$3:$S$17,0) -> 5 | N6: General Affair | O6: =MATCH(N6,$S$3:$S$20,0) -> 5 | P6: General Affair | Q6: =MATCH(P6,$S$3:$S$20,0) -> 5 | S6: Finance(Accounting/Cashier) | T6: IDL | U6: IDL others | AA6: Ironing
B7: General Affair ( HL ) | D7: General Affair ( HL ) | E7: =MATCH(D7,$S$3:$S$15,0) -> 6 | F7: HRD(Personnel/Payroll) | G7: =MATCH(F7,$S$3:$S$16,0) -> 8 | H7: General Affair | I7: =MATCH(H7,$S$3:$S$16,0) -> 5 | J7: HRD(Personnel/Payroll) | K7: =MATCH(J7,$S$3:$S$17,0) -> 8 | L7: HRD(Personnel/Payroll) | M7: =MATCH(L7,$S$3:$S$17,0) -> 8 | N7: HRD(Personnel/Payroll) | O7: =MATCH(N7,$S$3:$S$20,0) -> 8 | P7: HRD(Personnel/Payroll) | Q7: =MATCH(P7,$S$3:$S$20,0) -> 8 | S7: General Affair | T7: IDL | U7: IDL others | AA7: Packing
B8: HRD(Personnel/Payroll) | D8: HRD(Personnel/Payroll) | E8: =MATCH(D8,$S$3:$S$15,0) -> 8 | F8: Compliant/Purchasing/EDP(MIS) | G8: =MATCH(F8,$S$3:$S$16,0) -> 14 | H8: HRD(Personnel/Payroll) | I8: =MATCH(H8,$S$3:$S$16,0) -> 8 | J8: Compliant/Purchasing/EDP(MIS) | K8: =MATCH(J8,$S$3:$S$17,0) -> 14 | L8: Compliant/Purchasing/EDP(MIS) | M8: =MATCH(L8,$S$3:$S$17,0) -> 14 | N8: Compliant/EDP | O8: =MATCH(N8,$S$3:$S$20,0) -> 16 | P8: Compliant/EDP | Q8: =MATCH(P8,$S$3:$S$20,0) -> 16 | S8: General Affair ( HL ) | T8: IDL | U8: IDL others | V8: HL | AA8: Washing
B9: Policlinic(Nurse) | D9: Policlinic(Nurse) | E9: =MATCH(D9,$S$3:$S$15,0) -> 11 | F9: Temporary(HL) | G9: =MATCH(F9,$S$3:$S$16,0) -> 13 | H9: Policlinic(Nurse) | I9: =MATCH(H9,$S$3:$S$16,0) -> 11 | J9: Temporary Cleaning Service (HL) | K9: =MATCH(J9,$S$3:$S$17,0) -> 15 | L9: Temporary(HL) | M9: =MATCH(L9,$S$3:$S$17,0) -> 13 | N9: Temporary(HL) General Affair | O9: =MATCH(N9,$S$3:$S$20,0) -> 18 | P9: Temporary(HL) General Affair | Q9: =MATCH(P9,$S$3:$S$20,0) -> 18 | S9: Driver | T9: IDL | U9: IDL others | AA9: IDL Final part
B10: Purchasing/EDP | D10: Purchasing/EDP | E10: =MATCH(D10,$S$3:$S$15,0) -> 2 | F10: Exim | G10: =MATCH(F10,$S$3:$S$16,0) -> 9 | H10: Compliant/Purchasing/EDP(MIS) | I10: =MATCH(H10,$S$3:$S$16,0) -> 14 | J10: Exim | K10: =MATCH(J10,$S$3:$S$17,0) -> 9 | L10: Exim | M10: =MATCH(L10,$S$3:$S$17,0) -> 9 | N10: Purchasing | O10: =MATCH(N10,$S$3:$S$20,0) -> 17 | P10: Purchasing | Q10: =MATCH(P10,$S$3:$S$20,0) -> 17 | S10: HRD(Personnel/Payroll) | T10: IDL | U10: IDL others | AA10: Washing Fty
B11: Security | D11: Security | E11: =MATCH(D11,$S$3:$S$15,0) -> 1 | F11: Driver | G11: =MATCH(F11,$S$3:$S$16,0) -> 7 | H11: Security | I11: =MATCH(H11,$S$3:$S$16,0) -> 1 | J11: Driver | K11: =MATCH(J11,$S$3:$S$17,0) -> 7 | L11: Driver | M11: =MATCH(L11,$S$3:$S$17,0) -> 7 | N11: Driver | O11: =MATCH(N11,$S$3:$S$20,0) -> 7 | P11: Driver | Q11: =MATCH(P11,$S$3:$S$20,0) -> 7 | S11: Exim | T11: IDL | U11: IDL others | AA11: IDL Cutting
B12: Sekretaris | D12: Sekretaris | E12: =MATCH(D12,$S$3:$S$15,0) -> 12 | H12: Temporary(HL) | I12: =MATCH(H12,$S$3:$S$16,0) -> 13 | S12: security internal | T12: IDL | U12: IDL others | AA12: IDL Washing
B13: Temporary(HL) | D13: Temporary(HL) | E13: =MATCH(D13,$S$3:$S$15,0) -> 13 | S13: Policlinic(Nurse) | T13: IDL | U13: IDL others | AA13: IDL Washing Fty
S14: Sekretaris | T14: IDL | U14: IDL others | AA14: IDL Embordiary
B15: Manufacturing | D15: Manufacturing | F15: MANUFACTURING | H15: Manufacturing | J15: Manufacturing | L15: Manufacturing | N15: Manufacturing | P15: Manufacturing | S15: Temporary(HL) | T15: IDL | U15: IDL others | V15: HL | AA15: QC
B16: Pattern/POLA/Sample/Marker | C16: =MATCH(B16,$S$22:$S$288,0) -> 2 | D16: Pattern/POLA/Sample/Marker | E16: =MATCH(D16,$S$22:$S$288,0) -> 2 | F16: Pattern/POLA/Sample | G16: =MATCH(F16,$S$22:$S$288,0) -> 1 | H16: Pattern/POLA/Sample | I16: =MATCH(H16,$S$22:$S$288,0) -> 1 | J16: Pattern/POLA/Sample | K16: =MATCH(J16,$S$22:$S$288,0) -> 1 | L16: Pattern/POLA/Sample | M16: =MATCH(L16,$S$22:$S$288,0) -> 1 | N16: Pattern/POLA/Sample | O16: =MATCH(N16,$S$22:$S$288,0) -> 1 | P16: Pattern/POLA/Sample | S16: Compliant/Purchasing/EDP(MIS) | T16: IDL | U16: IDL others | AA16: Sample room
B17: Cutting | C17: =MATCH(B17,$S$22:$S$288,0) -> 3 | D17: Cutting | E17: =MATCH(D17,$S$22:$S$288,0) -> 3 | F17: Cutting | G17: =MATCH(F17,$S$22:$S$288,0) -> 3 | H17: Cutting | I17: =MATCH(H17,$S$22:$S$288,0) -> 3 | J17: Cutting | K17: =MATCH(J17,$S$22:$S$288,0) -> 3 | L17: Cutting | M17: =MATCH(L17,$S$22:$S$288,0) -> 3 | N17: Cutting | O17: =MATCH(N17,$S$22:$S$288,0) -> 3 | P17: Cutting | S17: Temporary Cleaning Service (HL) | T17: IDL | U17: IDL others | V17: HL | AA17: Sample center
B18: Cutting/staff | C18: =MATCH(B18,$S$22:$S$288,0) -> 5 | D18: Cutting/staff | E18: =MATCH(D18,$S$22:$S$288,0) -> 5 | F18: Cutting/Staff | G18: =MATCH(F18,$S$22:$S$288,0) -> 5 | H18: Cutting/staff | I18: =MATCH(H18,$S$22:$S$288,0) -> 5 | J18: Cutting/staff | K18: =MATCH(J18,$S$22:$S$288,0) -> 5 | L18: Cutting/staff | M18: =MATCH(L18,$S$22:$S$288,0) -> 5 | N18: Cutting/staff | O18: =MATCH(N18,$S$22:$S$288,0) -> 5 | P18: Cutting (SHIFT) | S18: Compliant/EDP | T18: IDL | U18: IDL others | AA18: Mechanic
B19: Cutting/piping | C19: =MATCH(B19,$S$22:$S$288,0) -> 6 | D19: Cutting/piping | E19: =MATCH(D19,$S$22:$S$288,0) -> 6 | F19: Cutting/Piping | G19: =MATCH(F19,$S$22:$S$288,0) -> 6 | H19: Cutting/piping | I19: =MATCH(H19,$S$22:$S$288,0) -> 6 | J19: Cutting/piping | K19: =MATCH(J19,$S$22:$S$288,0) -> 6 | L19: Cutting/piping | M19: =MATCH(L19,$S$22:$S$288,0) -> 6 | N19: Cutting/piping | O19: =MATCH(N19,$S$22:$S$288,0) -> 6 | P19: Cutting/staff | S19: Purchasing | T19: IDL | U19: IDL others | AA19: Warehouse
B20: Temporary Cutting (HL) | C20: =MATCH(B20,$S$22:$S$288,0) -> 12 | D20: Temporary Cutting (HL) | E20: =MATCH(D20,$S$22:$S$288,0) -> 12 | F20: Temporary Cutting (HL) | G20: =MATCH(F20,$S$22:$S$288,0) -> 12 | H20: Temporary Cutting (HL) | I20: =MATCH(H20,$S$22:$S$288,0) -> 12 | J20: Temporary Cutting (HL) | K20: =MATCH(J20,$S$22:$S$288,0) -> 12 | L20: Temporary Cutting (HL) | M20: =MATCH(L20,$S$22:$S$288,0) -> 12 | N20: Temporary Cutting (HL) | O20: =MATCH(N20,$S$22:$S$288,0) -> 12 | P20: Cutting/piping | S20: Temporary(HL) General Affair | T20: IDL | U20: IDL others | V20: HL | AA20: PPIC
B21: Sewing/staff | C21: =MATCH(B21,$S$22:$S$288,0) -> 20 | D21: Kantong Bobok | E21: =MATCH(D21,$S$22:$S$288,0) -> 13 | F21: Kantong Bobok | G21: =MATCH(F21,$S$22:$S$288,0) -> 13 | H21: Kantong Bobok | I21: =MATCH(H21,$S$22:$S$288,0) -> 13 | J21: Kantong Bobok | K21: =MATCH(J21,$S$22:$S$288,0) -> 13 | L21: Kantong Bobok | M21: =MATCH(L21,$S$22:$S$288,0) -> 13 | N21: Kantong Bobok | O21: =MATCH(N21,$S$22:$S$288,0) -> 13 | P21: Cutting (HL) | S21: Manufacturing | AA21: IDL Others
B22: Sewing Line -1 | C22: =MATCH(B22,$S$22:$S$288,0) -> 123 | D22: Temporary Bobok (HL) | E22: =MATCH(D22,$S$22:$S$288,0) -> 14 | F22: Temporary Kantong Bobok (HL) | G22: =MATCH(F22,$S$22:$S$288,0) -> 16 | H22: Sewing/staff | I22: =MATCH(H22,$S$22:$S$288,0) -> 20 | J22: Sewing/staff | K22: =MATCH(J22,$S$22:$S$288,0) -> 20 | L22: Sewing/staff | M22: =MATCH(L22,$S$22:$S$288,0) -> 20 | N22: Sewing/staff | O22: =MATCH(N22,$S$22:$S$288,0) -> 20 | P22: Cutting PLT (Training) | S22: Pattern/POLA/Sample | T22: IDL | U22: Sample room | AA22: IDL Packing
B23: Sewing Line -2 | C23: =MATCH(B23,$S$22:$S$288,0) -> 125 | D23: Sewing/staff | E23: =MATCH(D23,$S$22:$S$288,0) -> 20 | F23: Sewing/Staff | G23: =MATCH(F23,$S$22:$S$288,0) -> 20 | H23: Sewing Line - 1 | I23: =MATCH(H23,$S$22:$S$288,0) -> 124 | J23: Sewing Line -1 | K23: =MATCH(J23,$S$22:$S$288,0) -> 123 | L23: Sewing Line -1 | M23: =MATCH(L23,$S$22:$S$288,0) -> 123 | N23: Sewing Line -1 | O23: =MATCH(N23,$S$22:$S$288,0) -> 123 | P23: Chief Sewing | S23: Pattern/POLA/Sample/Marker | T23: IDL | U23: Sample room | AA23: IDL Ironing
B24: Sewing Line -3 | C24: =MATCH(B24,$S$22:$S$288,0) -> 127 | D24: Sewing Line -33 | E24: =MATCH(D24,$S$22:$S$288,0) -> 175 | F24: Sewing Line -1 | G24: =MATCH(F24,$S$22:$S$288,0) -> 123 | H24: Sewing Line - 2 | I24: =MATCH(H24,$S$22:$S$288,0) -> 126 | J24: Sewing Line -2 | K24: =MATCH(J24,$S$22:$S$288,0) -> 125 | L24: Sewing Line -2 | M24: =MATCH(L24,$S$22:$S$288,0) -> 125 | N24: Sewing Line -2 | O24: =MATCH(N24,$S$22:$S$288,0) -> 125 | P24: Supervisor Sewing | S24: Cutting | T24: DL | U24: Cutting | AA24: Pleating
B25: Sewing Line -4 | C25: =MATCH(B25,$S$22:$S$288,0) -> 131 | D25: Sewing Line -34 | E25: =MATCH(D25,$S$22:$S$288,0) -> 176 | F25: Sewing Line -2 | G25: =MATCH(F25,$S$22:$S$288,0) -> 125 | H25: Sewing Line - 3 | I25: =MATCH(H25,$S$22:$S$288,0) -> 128 | J25: Sewing Line -3 | K25: =MATCH(J25,$S$22:$S$288,0) -> 129 | L25: Sewing Line -3 | M25: =MATCH(L25,$S$22:$S$288,0) -> 127 | N25: Sewing Line -3 | O25: =MATCH(N25,$S$22:$S$288,0) -> 127 | P25: Sewing/staff | S25: Cutting (SHIFT) | T25: DL | U25: Cutting
B26: Sewing Line -5 | C26: =MATCH(B26,$S$22:$S$288,0) -> 133 | D26: Sewing Line -35 | E26: =MATCH(D26,$S$22:$S$288,0) -> 177 | F26: Sewing Line -3 | G26: =MATCH(F26,$S$22:$S$288,0) -> 127 | H26: Sewing Line - 4 | I26: =MATCH(H26,$S$22:$S$288,0) -> 132 | J26: Sewing Line -4 | K26: =MATCH(J26,$S$22:$S$288,0) -> 131 | L26: Sewing Line -4 | M26: =MATCH(L26,$S$22:$S$288,0) -> 131 | N26: Sewing Line -4 | O26: =MATCH(N26,$S$22:$S$288,0) -> 131 | P26: Sewing Line -1 | S26: Cutting/staff | T26: IDL | U26: IDL Cutting
B27: Sewing Line -6 | C27: =MATCH(B27,$S$22:$S$288,0) -> 135 | D27: Sewing Line -36 | E27: =MATCH(D27,$S$22:$S$288,0) -> 178 | F27: Sewing Line -4 | G27: =MATCH(F27,$S$22:$S$288,0) -> 131 | H27: Sewing Line - 5 | I27: =MATCH(H27,$S$22:$S$288,0) -> 134 | J27: Sewing Line -5 | K27: =MATCH(J27,$S$22:$S$288,0) -> 133 | L27: Sewing Line -5 | M27: =MATCH(L27,$S$22:$S$288,0) -> 133 | N27: Sewing Line -5 | O27: =MATCH(N27,$S$22:$S$288,0) -> 133 | P27: Sewing Line -2 | S27: Cutting/piping | T27: DL | U27: Cutting
B28: Sewing Line -7 | C28: =MATCH(B28,$S$22:$S$288,0) -> 137 | D28: Sewing Line -37 | E28: =MATCH(D28,$S$22:$S$288,0) -> 179 | F28: Sewing Line -5 | G28: =MATCH(F28,$S$22:$S$288,0) -> 133 | H28: Sewing Line - 6 | I28: =MATCH(H28,$S$22:$S$288,0) -> 136 | J28: Sewing Line -6 | K28: =MATCH(J28,$S$22:$S$288,0) -> 135 | L28: Sewing Line -6 | M28: =MATCH(L28,$S$22:$S$288,0) -> 135 | N28: Sewing Line -6 | O28: =MATCH(N28,$S$22:$S$288,0) -> 135 | P28: Sewing Line -3 | S28: Cutting/piping staff | T28: IDL | U28: IDL Cutting
B29: Sewing Line -8 | C29: =MATCH(B29,$S$22:$S$288,0) -> 139 | D29: Sewing Line -38 | E29: =MATCH(D29,$S$22:$S$288,0) -> 180 | F29: Sewing Line -6 | G29: =MATCH(F29,$S$22:$S$288,0) -> 135 | H29: Sewing Line - 7 | I29: =MATCH(H29,$S$22:$S$288,0) -> 138 | J29: Sewing Line -7 | K29: =MATCH(J29,$S$22:$S$288,0) -> 137 | L29: Sewing Line -7 | M29: =MATCH(L29,$S$22:$S$288,0) -> 137 | N29: Sewing Line -7 | O29: =MATCH(N29,$S$22:$S$288,0) -> 137 | P29: Sewing Line -3/ Shift | S29: Cutting (check Panel) | T29: IDL | U29: QC
B30: Sewing Line -9 | C30: =MATCH(B30,$S$22:$S$288,0) -> 141 | D30: Sewing Line -39 | E30: =MATCH(D30,$S$22:$S$288,0) -> 181 | F30: Sewing Line -7 | G30: =MATCH(F30,$S$22:$S$288,0) -> 137 | H30: Sewing Line - 8 | I30: =MATCH(H30,$S$22:$S$288,0) -> 140 | J30: Sewing Line -8 | K30: =MATCH(J30,$S$22:$S$288,0) -> 139 | L30: Sewing Line -8 | M30: =MATCH(L30,$S$22:$S$288,0) -> 139 | N30: Sewing Line -8 | O30: =MATCH(N30,$S$22:$S$288,0) -> 139 | P30: Sewing Line -4 | S30: Cutting (check Panel) HL | T30: IDL | U30: QC | V30: HL
B31: Sewing Line -10 | C31: =MATCH(B31,$S$22:$S$288,0) -> 144 | D31: Sewing Line -40 | E31: =MATCH(D31,$S$22:$S$288,0) -> 182 | F31: Sewing Line -8 | G31: =MATCH(F31,$S$22:$S$288,0) -> 139 | H31: Sewing Line - 9 | I31: =MATCH(H31,$S$22:$S$288,0) -> 142 | J31: Sewing Line -9 | K31: =MATCH(J31,$S$22:$S$288,0) -> 141 | L31: Sewing Line -9 | M31: =MATCH(L31,$S$22:$S$288,0) -> 141 | N31: Sewing Line -9 | O31: =MATCH(N31,$S$22:$S$288,0) -> 141 | P31: Sewing Line -5 | S31: Cutting (HL) | T31: DL | U31: Cutting | V31: HL
B32: Sewing Line -11 | C32: =MATCH(B32,$S$22:$S$288,0) -> 146 | D32: Sewing Line -41 | E32: =MATCH(D32,$S$22:$S$288,0) -> 183 | F32: Sewing Line -9 | G32: =MATCH(F32,$S$22:$S$288,0) -> 141 | H32: Sewing Line - 10 | I32: =MATCH(H32,$S$22:$S$288,0) -> 145 | J32: Sewing Line -10 | K32: =MATCH(J32,$S$22:$S$288,0) -> 144 | L32: Sewing Line -10 | M32: =MATCH(L32,$S$22:$S$288,0) -> 144 | N32: Sewing Line -10 | O32: =MATCH(N32,$S$22:$S$288,0) -> 144 | P32: Sewing Line -6 | S32: Cutting PLT (Training) | T32: DL | U32: Cutting | V32: HL
B33: Sewing Line -12 | C33: =MATCH(B33,$S$22:$S$288,0) -> 148 | D33: Sewing Line -42 | E33: =MATCH(D33,$S$22:$S$288,0) -> 184 | F33: Sewing Line -10 | G33: =MATCH(F33,$S$22:$S$288,0) -> 144 | H33: Sewing Line - 11 | I33: =MATCH(H33,$S$22:$S$288,0) -> 147 | J33: Sewing Line -11 | K33: =MATCH(J33,$S$22:$S$288,0) -> 146 | L33: Sewing Line -11 | M33: =MATCH(L33,$S$22:$S$288,0) -> 146 | N33: Sewing Line -11 | O33: =MATCH(N33,$S$22:$S$288,0) -> 146 | P33: Sewing Line -7 | S33: Temporary Cutting (HL) | T33: DL | U33: Cutting | V33: HL
B34: Sewing Line -13 | C34: =MATCH(B34,$S$22:$S$288,0) -> 152 | D34: Sewing Line -43 | E34: =MATCH(D34,$S$22:$S$288,0) -> 185 | F34: Sewing Line -11 | G34: =MATCH(F34,$S$22:$S$288,0) -> 146 | H34: Sewing Line - 12 | I34: =MATCH(H34,$S$22:$S$288,0) -> 149 | J34: Sewing Line -12 | K34: =MATCH(J34,$S$22:$S$288,0) -> 150 | L34: Sewing Line -12 | M34: =MATCH(L34,$S$22:$S$288,0) -> 148 | N34: Sewing Line -12 | O34: =MATCH(N34,$S$22:$S$288,0) -> 148 | P34: Sewing Line -8 | S34: Kantong Bobok | T34: DL | U34: Sewing
B35: Sewing Line -14 | C35: =MATCH(B35,$S$22:$S$288,0) -> 153 | D35: Sewing Line -44 | E35: =MATCH(D35,$S$22:$S$288,0) -> 186 | F35: Sewing Line -12 | G35: =MATCH(F35,$S$22:$S$288,0) -> 148 | H35: Sewing Sample | I35: =MATCH(H35,$S$22:$S$288,0) -> #N/A | J35: Sewing Line -13 | K35: =MATCH(J35,$S$22:$S$288,0) -> 152 | L35: Sewing Line -13 | M35: =MATCH(L35,$S$22:$S$288,0) -> 152 | N35: Sewing Line -13 | O35: =MATCH(N35,$S$22:$S$288,0) -> 152 | P35: Sewing Line -9 | S35: Temporary Bobok (HL) | T35: DL | U35: Sewing | V35: HL
B36: Sewing Line -15 | C36: =MATCH(B36,$S$22:$S$288,0) -> 154 | D36: Sewing Line -45 | E36: =MATCH(D36,$S$22:$S$288,0) -> 187 | F36: Sewing Line -13 | G36: =MATCH(F36,$S$22:$S$288,0) -> 152 | H36: Temporary Sewing(HL) | I36: =MATCH(H36,$S$22:$S$288,0) -> 204 | J36: Sewing Line -14 | K36: =MATCH(J36,$S$22:$S$288,0) -> 153 | L36: Sewing Line -14 | M36: =MATCH(L36,$S$22:$S$288,0) -> 153 | N36: Sewing Line -14 | O36: =MATCH(N36,$S$22:$S$288,0) -> 153 | P36: Sewing Line -9/ Shift | S36: Temporary Sample/Kantong Bobok (HL) | T36: DL | U36: Sewing | V36: HL
B37: Sewing Line -16 | C37: =MATCH(B37,$S$22:$S$288,0) -> 155 | D37: Sewing Line -46 | E37: =MATCH(D37,$S$22:$S$288,0) -> 188 | F37: Sewing Line -14 | G37: =MATCH(F37,$S$22:$S$288,0) -> 153 | H37: Temporary Special production | I37: =MATCH(H37,$S$22:$S$288,0) -> 213 | J37: Sewing Line -15 | K37: =MATCH(J37,$S$22:$S$288,0) -> 154 | L37: Sewing Line -15 | M37: =MATCH(L37,$S$22:$S$288,0) -> 154 | N37: Sewing Line -15 | O37: =MATCH(N37,$S$22:$S$288,0) -> 154 | P37: Sewing Line -10 | S37: Temporary Kantong Bobok (HL) | T37: DL | U37: Sewing | V37: HL
B38: Sewing Line -17 | C38: =MATCH(B38,$S$22:$S$288,0) -> 156 | D38: Sewing Line -47 | E38: =MATCH(D38,$S$22:$S$288,0) -> 189 | F38: Sewing Line -15 | G38: =MATCH(F38,$S$22:$S$288,0) -> 154 | H38: Transfer/sewing | I38: =MATCH(H38,$S$22:$S$288,0) -> 206 | J38: Sewing Line -16 | K38: =MATCH(J38,$S$22:$S$288,0) -> 155 | L38: Sewing Line -16 | M38: =MATCH(L38,$S$22:$S$288,0) -> 155 | N38: Sewing Line -16 | O38: =MATCH(N38,$S$22:$S$288,0) -> 155 | P38: Sewing Line -11 | S38: Cutting sewing | T38: DL | U38: Cutting
B39: Sewing Line -18 | C39: =MATCH(B39,$S$22:$S$288,0) -> 157 | D39: Sewing Line -48 | E39: =MATCH(D39,$S$22:$S$288,0) -> 190 | F39: Sewing Line -16 | G39: =MATCH(F39,$S$22:$S$288,0) -> 155 | H39: Transfer/Finishing | I39: =MATCH(H39,$S$22:$S$288,0) -> 215 | J39: Sewing Line -17 | K39: =MATCH(J39,$S$22:$S$288,0) -> 156 | L39: Sewing Line -17 | M39: =MATCH(L39,$S$22:$S$288,0) -> 156 | N39: Sewing Line -17 | O39: =MATCH(N39,$S$22:$S$288,0) -> 156 | P39: Sewing Line -12 | S39: Chief Sewing | T39: IDL | U39: IDL Sewing
B40: Sewing Line -19 | C40: =MATCH(B40,$S$22:$S$288,0) -> 159 | D40: Sewing Line -49 | E40: =MATCH(D40,$S$22:$S$288,0) -> 191 | F40: Sewing Line -17 | G40: =MATCH(F40,$S$22:$S$288,0) -> 156 | H40: Repair | I40: =MATCH(H40,$S$22:$S$288,0) -> 219 | J40: Sewing Line -18 | K40: =MATCH(J40,$S$22:$S$288,0) -> 158 | L40: Sewing Line -18 | M40: =MATCH(L40,$S$22:$S$288,0) -> 157 | N40: Sewing Line -18 | O40: =MATCH(N40,$S$22:$S$288,0) -> 157 | P40: Sewing Line -12/ Shift | S40: Supervisor Sewing | T40: IDL | U40: IDL Sewing
...

Sheet GLD
A1: PT. GLORY INDUSTRIAL SEMARANG DEMAK
A2: DAILY REPORT - EMPLOYEE
A4: DATE : August 11, 2026
B5: DEPARTEMENT | C5: Employee Yesterday | G5: Total | H5: Employee Today | P5: Transferance | X5: TOTAL | Y5: Absence | AW5: Total Absence | AY5: Total employee | BC5: Total | BD5: REMARKS
H6: In | L6: Out | P6: In | T6: Out | Y6: WN | AC6: S | AG6: P | AK6: OL | AO6: CN | AS6: CM
C7: Permanen | E7: Contract | H7: P | J7: C | L7: P | N7: C | P7: P | R7: C | T7: P | V7: C | Y7: P | AA7: C | AC7: P | AE7: C | AG7: P | AI7: C | AK7: P | AM7: C | AO7: P | AQ7: C | AS7: P | AU7: C | AW7: P | AX7: C | AY7: Permanen | BA7: Contract
C8: M | D8: F | E8: M | F8: F | H8: M | I8: F | J8: M | K8: F | L8: M | M8: F | N8: M | O8: F | P8: M | Q8: F | R8: M | S8: F | T8: M | U8: F | V8: M | W8: F | Y8: M | Z8: F | AA8: M | AB8: F | AC8: M | AD8: F | AE8: M | AF8: F | AG8: M | AH8: F | AI8: M | AJ8: F | AK8: M | AL8: F | AM8: M | AN8: F | AO8: M | AP8: F | AQ8: M | AR8: F | AS8: M | AT8: F | AU8: M | AV8: F | AY8: M | AZ8: F | BA8: M | BB8: F | BE8: dept.name
A9: 1 | B9: DIRECTOR | C9: 0 | D9: 0 | E9: 0 | F9: 0 | G9: 0 | X9: 0 | AW9: 0 | AX9: 0 | AY9: 0 | AZ9: 0 | BA9: 0 | BB9: 0 | BC9: 0
A10: 2 | B10: Factory Manager (Senior) | C10: 1 | D10: 0 | E10: 0 | F10: 0 | G10: 1 | X10: 1 | AW10: 0 | AX10: 0 | AY10: 1 | AZ10: 0 | BA10: 0 | BB10: 0 | BC10: 1 | BD10: Mr. Chad Hsu
A11: 3 | B11: Factory Manager | C11: 5 | D11: 0 | E11: 0 | F11: 0 | G11: 5 | X11: 5 | AW11: 0 | AX11: 0 | AY11: 5 | AZ11: 0 | BA11: 0 | BB11: 0 | BC11: 5 | BD11: Mr. SIMON, Mr.Van , Mr. James. Mr.David w, Mr.Brady chiang
A12: 4 | B12: Head Office (HO) | C12: 2 | D12: 2 | E12: 0 | F12: 0 | G12: 4 | X12: 4 | AW12: 0 | AX12: 0 | AY12: 2 | AZ12: 2 | BA12: 0 | BB12: 0 | BC12: 4 | BD12: .Mr. Mike. Mr. Danny,Melita Mulyani,Jerim
A13: 5 | B13: Advisor-PPIC | C13: 2 | D13: 2 | E13: 0 | F13: 0 | G13: 4 | X13: 4 | AW13: 0 | AX13: 0 | AY13: 2 | AZ13: 2 | BA13: 0 | BB13: 0 | BC13: 4 | BD13: Ms. Miko. Mr.Jerry, Ms.Janet, Mr.Andy
A14: 6 | B14: Advisor-Cutting | C14: 1 | D14: 0 | E14: 0 | F14: 0 | G14: 1 | X14: 1 | AW14: 0 | AX14: 0 | AY14: 1 | AZ14: 0 | BA14: 0 | BB14: 0 | BC14: 1 | BD14: Mr. Lan you zhang. .Mr.Zhong daizhou
A15: 7 | B15: Advisor-Sewing | C15: 2 | D15: 10 | E15: 0 | F15: 0 | G15: 12 | X15: 12 | AW15: 0 | AX15: 0 | AY15: 2 | AZ15: 10 | BA15: 0 | BB15: 0 | BC15: 12 | BD15: LIU JIE, HUANG GAN TIEN, LI PING,ZHOU ZHIBIN, GUO YIN HUA, GUO HONG MEI,YANG XIAO-LING, ZOU XIA, HUANG CAIPING,CAI KENGSHUI, QIN ZHIGANG,chou
A16: 8 | B16: Advisor-Finishing | C16: 0 | D16: 1 | E16: 0 | F16: 0 | G16: 1 | X16: 1 | AW16: 0 | AX16: 0 | AY16: 0 | AZ16: 1 | BA16: 0 | BB16: 0 | BC16: 1 | BD16: Ms. Imelda
A17: 10 | B17: Advisor-Pattern/ Sample | C17: 1 | D17: 4 | E17: 0 | F17: 0 | G17: 5 | X17: 5 | AW17: 0 | AX17: 0 | AY17: 1 | AZ17: 4 | BA17: 0 | BB17: 0 | BC17: 5 | BD17: Chantal Yang,, Zheng Yi,Bao Xianggang.Qin. Kristy, cai
A18: 11 | B18: Advisor/Manager QA | C18: 2 | D18: 0 | E18: 0 | F18: 0 | G18: 2 | X18: 2 | AW18: 0 | AX18: 0 | AY18: 2 | AZ18: 0 | BA18: 0 | BB18: 0 | BC18: 2 | BD18: Mr. Fly, Jay Chang,
A19: 12 | B19: Others | C19: 1 | D19: 0 | E19: 0 | F19: 0 | G19: 1 | X19: 1 | AW19: 0 | AX19: 0 | AY19: 1 | AZ19: 0 | BA19: 0 | BB19: 0 | BC19: 1 | BD19: Bujon Guo,
AW20: 0 | AX20: 0 | AY20: 0 | AZ20: 0 | BA20: 0 | BB20: 0
A21: I | B21: Administration | C21: 0 | D21: 0 | E21: 0 | F21: 0 | G21: 0 | AW21: 0 | AX21: 0 | AY21: 0 | AZ21: 0 | BA21: 0 | BB21: 0 | BC21: 0
A22: 1 | B22: Finance(Accounting/Cashier) | C22: 0 | D22: 1 | E22: 2 | F22: 3 | G22: 6 | X22: 6 | AW22: 0 | AX22: 0 | AY22: 0 | AZ22: 1 | BA22: 2 | BB22: 3 | BC22: 6 | BE22: Finance
A23: 2 | B23: General Affair | C23: 0 | D23: 0 | E23: 7 | F23: 3 | G23: 10 | X23: 10 | AW23: 0 | AX23: 0 | AY23: 0 | AZ23: 0 | BA23: 7 | BB23: 3 | BC23: 10 | BE23: General Affair
A24: 3 | B24: Cleaning Cervice | C24: 0 | D24: 0 | E24: 6 | F24: 2 | G24: 8 | X24: 8 | AW24: 0 | AX24: 0 | AY24: 0 | AZ24: 0 | BA24: 6 | BB24: 2 | BC24: 8
A25: 4 | B25: Cleaning Cervice - 2 | C25: 0 | D25: 0 | E25: 4 | F25: 1 | G25: 5 | X25: 5 | AW25: 0 | AX25: 0 | AY25: 0 | AZ25: 0 | BA25: 4 | BB25: 1 | BC25: 5
A26: 5 | B26: Cleaning Cervice - 3 | C26: 0 | D26: 0 | E26: 3 | F26: 1 | G26: 4 | X26: 4 | AW26: 0 | AX26: 0 | AY26: 0 | AZ26: 0 | BA26: 3 | BB26: 1 | BC26: 4
A27: 6 | B27: Cleaning Cervice - 5 | C27: 0 | D27: 0 | E27: 5 | F27: 1 | G27: 6 | X27: 6 | AW27: 0 | AX27: 0 | AY27: 0 | AZ27: 0 | BA27: 5 | BB27: 1 | BC27: 6
A28: 7 | B28: Cleaning Cervice - 6 | C28: 0 | D28: 0 | E28: 3 | F28: 1 | G28: 4 | X28: 4 | AW28: 0 | AX28: 0 | AY28: 0 | AZ28: 0 | BA28: 3 | BB28: 1 | BC28: 4
A29: 8 | B29: HRD(Personnel/Payroll) | C29: 3 | D29: 8 | E29: 0 | F29: 1 | G29: 12 | X29: 12 | AW29: 0 | AX29: 0 | AY29: 3 | AZ29: 8 | BA29: 0 | BB29: 1 | BC29: 12 | BE29: HRD
A30: 9 | B30: Compliant (HO) | C30: 1 | D30: 1 | E30: 1 | F30: 1 | G30: 4 | X30: 4 | AW30: 0 | AX30: 0 | AY30: 1 | AZ30: 1 | BA30: 1 | BB30: 1 | BC30: 4 | BE30: Compliant/EDP
A31: 10 | B31: EDP (HO) | C31: 3 | D31: 0 | E31: 0 | F31: 0 | G31: 3 | X31: 3 | AW31: 0 | AX31: 0 | AY31: 3 | AZ31: 0 | BA31: 0 | BB31: 0 | BC31: 3
A32: 11 | B32: Barcode (HO) | C32: 0 | D32: 5 | E32: 0 | F32: 0 | G32: 5 | X32: 5 | AT32: 1 | AW32: 1 | AX32: 0 | AY32: 0 | AZ32: 4 | BA32: 0 | BB32: 0 | BC32: 4 | BD32: MISKHUT TOYIBAH (CM)
A33: 12 | B33: Internal Auditor (HO) | C33: 0 | D33: 0 | E33: 1 | F33: 7 | G33: 8 | X33: 8 | AW33: 0 | AX33: 0 | AY33: 0 | AZ33: 0 | BA33: 1 | BB33: 7 | BC33: 8
A34: 13 | B34: QA Team (HO) | C34: 1 | D34: 15 | E34: 1 | F34: 5 | G34: 22 | X34: 22 | AW34: 0 | AX34: 0 | AY34: 1 | AZ34: 15 | BA34: 1 | BB34: 5 | BC34: 22
A35: 14 | B35: Purchasing | C35: 0 | D35: 1 | E35: 0 | F35: 0 | G35: 1 | X35: 1 | AW35: 0 | AX35: 0 | AY35: 0 | AZ35: 1 | BA35: 0 | BB35: 0 | BC35: 1 | BE35: Purchasing
A36: 15 | B36: Driver | C36: 1 | D36: 0 | E36: 3 | F36: 0 | G36: 4 | X36: 4 | AW36: 0 | AX36: 0 | AY36: 1 | AZ36: 0 | BA36: 3 | BB36: 0 | BC36: 4
A37: 16 | B37: Policlinic(Nurse) | C37: 0 | D37: 1 | E37: 0 | F37: 0 | G37: 1 | X37: 1 | AW37: 0 | AX37: 0 | AY37: 0 | AZ37: 1 | BA37: 0 | BB37: 0 | BC37: 1 | BE37: Policlinic
C38: 0 | D38: 0 | E38: 0 | F38: 0 | G38: 0
B40: Sub-total I | C40: 26 | D40: 51 | E40: 36 | F40: 26 | G40: 139 | H40: 0 | I40: 0 | J40: 0 | K40: 0 | L40: 0 | M40: 0 | N40: 0 | O40: 0 | P40: 0 | Q40: 0 | R40: 0 | S40: 0 | T40: 0 | U40: 0 | V40: 0 | W40: 0 | X40: 139 | Y40: 0 | Z40: 0 | AA40: 0 | AB40: 0 | AC40: 0 | AD40: 0 | AE40: 0 | AF40: 0 | AG40: 0 | AH40: 0 | AI40: 0 | AJ40: 0 | AK40: 0 | AL40: 0 | AM40: 0 | AN40: 0 | AO40: 0 | AP40: 0 | AQ40: 0 | AR40: 0 | AS40: 0 | AT40: 1 | AU40: 0 | AV40: 0 | AW40: 1 | AX40: 0 | AY40: 26 | AZ40: 50 | BA40: 36 | BB40: 26 | BC40: 138 | BD40: Total Absence = 1 Persons | BE40: Sub-total I
A41: II | B41: Manufacturing | X41: 0 | AW41: 0 | AX41: 0
A42: 1 | B42: Pattern/POLA/Sample | C42: 16 | D42: 36 | E42: 4 | F42: 19 | G42: 75 | X42: 75 | Y42: 2 | AT42: 1 | AW42: 3 | AX42: 0 | AY42: 14 | AZ42: 35 | BA42: 4 | BB42: 19 | BC42: 72 | BD42: RINI OKTAFIYAH (CM), FARIZI, SALIM (WN) | BE42: Pattern/POLA/Sample
...

Sheet GLD分攤(Chad)
A1: NO | B1: DEPARTEMENT | C1: 小類 | D1: 廠別 | E1: Employee Yesterday | I1: Total | J1: Employee Today | R1: Transferance
A2: 1 | B2: DIRECTOR | C2: - | D2: - | E2: 0 | F2: 0 | G2: 0 | H2: 0 | I2: =E2+F2+G2+H2 -> 0
A3: 2 | B3: Factory Manager (Senior) | C3: - | D3: - | E3: 1 | F3: 0 | G3: 0 | H3: 0 | I3: =E3+F3+G3+H3 -> 1
A4: 3 | B4: Factory Manager | C4: - | D4: - | E4: 3 | F4: 0 | G4: 0 | H4: 0 | I4: =E4+F4+G4+H4 -> 3
A5: 4 | B5: Head Office (HO) | C5: - | D5: - | E5: 0 | F5: 4 | G5: 0 | H5: 0 | I5: =E5+F5+G5+H5 -> 4
A6: 5 | B6: Advisor-PPIC | C6: - | D6: - | E6: 3 | F6: 0 | G6: 0 | H6: 0 | I6: =E6+F6+G6+H6 -> 3
A7: 6 | B7: Advisor-Cutting | C7: - | D7: - | E7: 0 | F7: 14 | G7: 0 | H7: 0 | I7: =E7+F7+G7+H7 -> 14
A8: 7 | B8: Advisor-Sewing | C8: - | D8: - | E8: 1 | F8: 1 | G8: 0 | H8: 0 | I8: =E8+F8+G8+H8 -> 2
A9: 8 | B9: Advisor-Finishing | C9: - | D9: - | E9: 2 | F9: 0 | G9: 0 | H9: 0 | I9: =E9+F9+G9+H9 -> 2
A10: 9 | B10: Advisor-Fabric | C10: - | D10: - | E10: 2 | F10: 2 | G10: 0 | H10: 0 | I10: =E10+F10+G10+H10 -> 4
A11: 10 | B11: Advisor-Pattern/ Sample | C11: - | D11: - | E11: 3 | F11: 0 | G11: 0 | H11: 0 | I11: =E11+F11+G11+H11 -> 3
A12: 11 | B12: Advisor-QC | C12: - | D12: - | E12: 1 | F12: 0 | G12: 0 | H12: 0 | I12: =E12+F12+G12+H12 -> 1
A13: 12 | B13: Advisor-Mechanic | C13: - | D13: - | E13: 0 | F13: 0 | G13: 0 | H13: 0 | I13: =E13+F13+G13+H13 -> 0
C14: - | D14: - | E14: 0 | F14: 0 | G14: 0 | H14: 0 | I14: =E14+F14+G14+H14 -> 0
A15: I | B15: Administration
A16: 1 | B16: Finance(Accounting/Cashier) | D16: GLD1+2+3+5+6 | I16: =E16+F16+G16+H16 -> 0
A17: 2 | B17: General Affair | C17: - | D17: GLD1+2+3+5+6 | E17: 2 | F17: 4 | G17: 0 | H17: 0 | I17: =E17+F17+G17+H17 -> 6
A18: 3 | B18: Cleaning Cervice | C18: - | D18: GLD1
A19: 4 | B19: Cleaning Cervice - 2 | C19: - | D19: GLD2
A20: 5 | B20: Cleaning Cervice - 3 | C20: - | D20: GLD3
A21: 6 | B21: Cleaning Cervice - 5 | C21: - | D21: GLD5
A22: 7 | B22: Cleaning Cervice - 6 | C22: - | D22: GLD6
A23: 8 | B23: HRD(Personnel/Payroll) | C23: - | D23: GLD1+2+3+5+6 | E23: 0 | F23: 0 | G23: 1 | H23: 2 | I23: =E23+F23+G23+H23 -> 3
A24: 9 | B24: Compliant/EDP/internal Audit (HO) | C24: - | D24: GLD1+2+3+5+6 | E24: 2 | F24: 4 | G24: 0 | H24: 3 | I24: =E24+F24+G24+H24 -> 9
A25: 10 | B25: Compliant/EDP (HO) | C25: - | D25: GLD1+2+3+5+6
A26: 11 | B26: Internal Auditor (HO) | C26: - | D26: GLD1+2+3+5+6
A27: 12 | B27: QA Team (HO) | D27: GLD1+2+3+5+6
A28: 13 | B28: Compliant (HO) | D28: GLD1+2+3+5+6
A29: 14 | B29: EDP (HO) | D29: GLD1+2+3+5+6
A30: 15 | B30: QA (HO) | C30: - | D30: GLD1+2+3+5+6
A31: 16 | B31: QC AUDITOR (HO) | D31: GLD1+2+3+5+6
A32: 17 | B32: Purchasing | C32: - | D32: GLD1+2+3+5+6 | E32: 2 | F32: 1 | G32: 1 | H32: 7 | I32: =E32+F32+G32+H32 -> 11
A33: 18 | B33: Driver | C33: - | D33: GLD1+2+3+5+6 | E33: 0 | F33: 2 | G33: 0 | H33: 0 | I33: =E33+F33+G33+H33 -> 2
A34: 19 | B34: Policlinic(Nurse) | C34: - | D34: GLD1+2+3+5+6 | E34: 0 | F34: 0 | G34: 5 | H34: 0 | I34: =E34+F34+G34+H34 -> 5
A35: 20 | B35: Auditor Sewing | C35: - | D35: GLD1+2+3+5+6 | E35: 0 | F35: 0 | G35: 0 | H35: 1 | I35: =E35+F35+G35+H35 -> 1
E36: 0 | F36: 0 | G36: 0 | H36: 0 | I36: =E36+F36+G36+H36 -> 0
B37: Sub-total I
A38: II | B38: Manufacturing | E38: 22 | F38: 32 | G38: 7 | H38: 13 | I38: =SUM(I2:I36) -> 74 | J38: 0 | K38: 0 | L38: 0 | M38: 0 | N38: 0 | O38: 0 | P38: 0 | Q38: 0 | R38: 0 | S38: 0 | T38: 0 | U38: 0 | V38: 0 | W38: 0 | X38: 0 | Y38: 0
A39: 1 | B39: Pattern/POLA/Sample | D39: GLD1+2+3+5+6
A40: 2 | B40: Cutting/piping (HL) | C40: 裁燙包人數 | D40: GLD1+2+3+5+6 | E40: 13 | F40: 19 | G40: 9 | H40: 21 | I40: =E40+F40+G40+H40 -> 62
...

Sheet Combine (不許動)
A1: GLD | B1: =COUNTIF(B2:B433,"NO") -> 0 | C1: Sewing | D1: HL | E1: 全廠扣 MNG、加 SL (確保數字都抓到) | H1: =IF((SUMIFS(F3:F340,A3:A340,"<>*total*")-SUMIFS(F3:F340,A3:A340,"*QC*GU*")<>'TP Summary'!S24),"ERROR","OK") -> OK | J1: 36 | M1: 40 | P1: 16 | S1: 20 | V1: 20
A2: DEPARTEMENT | B2: check | C2: DL/IDL | D2: Belong | E2: HL | F2: Total | G2: CM-P | H2: CM-C | J2: GLD1 | K2: GLD1-HL | L2: GLD1-CM | M2: GLD2 | N2: GLD2-HL | O2: GLD2-CM | P2: GLD3 | Q2: GLD3-HL | R2: GLD3-CM | S2: GLD5 | T2: GLD5-HL | U2: GLD5-CM | V2: GLD6 | W2: GLD6-HL | X2: GLD6-CM
A3: =GLD!B22 -> Finance(Accounting/Cashier) | B3: =IF(OR(A3=0,LEFT(A3,2)="Mr",LEFT(A3,2)="Ms",LEFT(A3,3)="Sub",LEFT(A3,5)="Grand",RIGHT(A3,3)="by,"),"",IF(ISERROR(MATCH(A3,'Dept (不許動)'!$S:$S,0)),"NO","")) | C3: =IF(A3=0,"",IF(ISNA(VLOOKUP(A3,'Dept (不許動)'!$S:$V,2,0)),"",VLOOKUP(A3,'Dept (不許動)'!$S:$V,2,0))) -> IDL | D3: =IF(A3=0,"",IF(ISNA(VLOOKUP(A3,'Dept (不許動)'!$S:$V,3,0)),"",VLOOKUP(A3,'Dept (不許動)'!$S:$V,3,0))) -> IDL others | E3: =IF(A3=0,"",IF(ISNA(VLOOKUP(A3,'Dept (不許動)'!$S:$V,4,0)),"",VLOOKUP(A3,'Dept (不許動)'!$S:$V,4,0))) -> 0 | F3: =GLD!$BC22 -> 6 | G3: =GLD!$AT22 -> 0 | H3: =GLD!$AV22 -> 0 | I3: =IF($D3="Embordiary","GLD6",IF(ISNA(VLOOKUP(A3,'GLD分攤(Chad)'!$B$2:$E$572,3,0)),"",(VLOOKUP(A3,'GLD分攤(Chad)'!$B$9:$E$572,3,0)))) -> GLD1+2+3+5+6 | J3: =IF(E3="HL",0,IF($I3="GLD1+2+3+5+6",$F3*$J$1/SUM($J$1:$V$1),IF($I3="GLD1+2+3",$F3*$J$1/SUM($J$1:$P$1),IF($I3="GLD1+2",$F3*$J$1/SUM($J$1:$M$1),IF($I3="GLD1",$F3,0))))) -> 1.6363636 | K3: =IF(E3="HL",IF($I3="GLD1+2+3+5+6",$F3*$J$1/SUM($J$1:$V$1),IF($I3="GLD1+2+3",$F3*$J$1/SUM($J$1:$P$1),IF($I3="GLD1+2",$F3*$J$1/SUM($J$1:$M$1),IF($I3="GLD1",$F3,0)))),0) -> 0 | L3: =IF($I3="GLD1+2+3+5+6",SUM($G3:$H3)*$J$1/SUM($J$1:$V$1),IF($I3="GLD1+2+3",SUM($G3:$H3)*$J$1/SUM($J$1:$P$1),IF($I3="GLD1+2+3",SUM($G3:$H3)*$J$1/SUM($J$1:$P$1),IF($I3="GLD1+2",SUM($G3:$H3)*$J$1/SUM($J$1:$M$1),IF($I3="GLD1",SUM($G3:$H3),0))))) -> 0 | M3: =IF(E3="HL",0,IF($I3="GLD1+2+3+5+6",$F3*$M$1/SUM($J$1:$V$1),IF($I3="GLD1+2+3",$F3*$M$1/SUM($J$1:$P$1),IF($I3="GLD1+2",$F3*$M$1/SUM($J$1:$M$1),IF($I3="GLD2",$F3,0))))) -> 1.8181818 | N3: =IF(E3="HL",IF($I3="GLD1+2+3+5+6",$F3*$M$1/SUM($J$1:$V$1),IF($I3="GLD1+2+3",$F3*$M$1/SUM($J$1:$P$1),IF($I3="GLD1+2",$F3*$M$1/SUM($J$1:$M$1),IF($I3="GLD2",$F3,0)))),0) -> 0 | O3: =IF($I3="GLD1+2+3+5+6",SUM($G3:$H3)*$M$1/SUM($J$1:$V$1),IF($I3="GLD1+2+3",SUM($G3:$H3)*$M$1/SUM($J$1:$P$1),IF($I3="GLD1+2+3",SUM($G3:$H3)*$M$1/SUM($J$1:$P$1),IF($I3="GLD1+2",SUM($G3:$H3)*$M$1/SUM($J$1:$M$1),IF($I3="GLD2",SUM($G3:$H3),0))))) -> 0 | P3: =IF(E3="HL",0,IF($I3="GLD1+2+3+5+6",$F3*$P$1/SUM($J$1:$V$1),IF($I3="GLD3+5",$F3*$P$1/SUM($P$1:$S$1),IF($I3="GLD1+2",0,IF($I3="GLD3",$F3,0))))) -> 0.72727273 | Q3: =IF(E3="HL",IF($I3="GLD1+2+3+5+6",$F3*$P$1/SUM($J$1:$V$1),IF($I3="GLD3+5",$F3*$P$1/SUM($P$1:$S$1),IF($I3="GLD1+2",0,IF($I3="GLD3",$F3,0)))),0) -> 0 | R3: =IF($I3="GLD1+2+3+5+6",SUM($G3:$H3)*$P$1/SUM($J$1:$V$1),IF($I3="GLD3+5",SUM($G3:$H3)*$P$1/SUM($P$1:$S$1),IF($I3="GLD1+2",0,IF($I3="GLD3",SUM($G3:$H3),0)))) -> 0 | S3: =IF(E3="HL",0,IF($I3="GLD1+2+3+5+6",$F3*$S$1/SUM($J$1:$V$1),IF($I3="GLD3+5",$F3*$S$1/SUM($P$1:$S$1),IF($I3="GLD5",$F3,0)))) -> 0.90909091 | T3: =IF(E3="HL",IF($I3="GLD1+2+3+5+6",$F3*$S$1/SUM($J$1:$V$1),IF($I3="GLD3+5",$F3*$S$1/SUM($P$1:$S$1),IF($I3="GLD5",$F3,0))),0) -> 0 | U3: =IF($I3="GLD1+2+3+5+6",SUM($G3:$H3)*$S$1/SUM($J$1:$V$1),IF($I3="GLD3+5",SUM($G3:$H3)*$S$1/SUM($P$1:$S$1),IF($I3="GLD5",SUM($G3:$H3),0))) -> 0 | V3: =IF(E3="HL",0,IF($I3="GLD1+2+3+5+6",$F3*$V$1/SUM($J$1:$V$1),IF($I3="GLD6",$F3,0))) -> 0.90909091 | W3: =IF(E3="HL",IF($I3="GLD1+2+3+5+6",$F3*$V$1/SUM($J$1:$V$1),IF($I3="GLD6",$F3,0)),0) -> 0 | X3: =IF($I3="GLD1+2+3+5+6",SUM($G3:$H3)*$V$1/SUM($J$1:$V$1),IF($I3="GLD6",SUM($G3:$H3),0)) -> 0 | Y3: =IF(E3="HL",F3-(K3+N3+Q3+T3+W3),F3-(J3+M3+P3+S3+V3)) -> 0 | Z3: =IF(ABS(SUM(J3:X3)-(F3+G3+H3))>=1,"check","")
A4: =GLD!B23 -> General Affair | B4: =IF(OR(A4=0,LEFT(A4,2)="Mr",LEFT(A4,2)="Ms",LEFT(A4,3)="Sub",LEFT(A4,5)="Grand",RIGHT(A4,3)="by,"),"",IF(ISERROR(MATCH(A4,'Dept (不許動)'!$S:$S,0)),"NO","")) | C4: =IF(A4=0,"",IF(ISNA(VLOOKUP(A4,'Dept (不許動)'!$S:$V,2,0)),"",VLOOKUP(A4,'Dept (不許動)'!$S:$V,2,0))) -> IDL | D4: =IF(A4=0,"",IF(ISNA(VLOOKUP(A4,'Dept (不許動)'!$S:$V,3,0)),"",VLOOKUP(A4,'Dept (不許動)'!$S:$V,3,0))) -> IDL others | E4: =IF(A4=0,"",IF(ISNA(VLOOKUP(A4,'Dept (不許動)'!$S:$V,4,0)),"",VLOOKUP(A4,'Dept (不許動)'!$S:$V,4,0))) -> 0 | F4: =GLD!$BC23 -> 10 | G4: =GLD!$AT23 -> 0 | H4: =GLD!$AV23 -> 0 | I4: =IF($D4="Embordiary","GLD6",IF(ISNA(VLOOKUP(A4,'GLD分攤(Chad)'!$B$2:$E$572,3,0)),"",(VLOOKUP(A4,'GLD分攤(Chad)'!$B$9:$E$572,3,0)))) -> GLD1+2+3+5+6 | J4: =IF(E4="HL",0,IF($I4="GLD1+2+3+5+6",$F4*$J$1/SUM($J$1:$V$1),IF($I4="GLD1+2+3",$F4*$J$1/SUM($J$1:$P$1),IF($I4="GLD1+2",$F4*$J$1/SUM($J$1:$M$1),IF($I4="GLD1",$F4,0))))) -> 2.7272727 | K4: =IF(E4="HL",IF($I4="GLD1+2+3+5+6",$F4*$J$1/SUM($J$1:$V$1),IF($I4="GLD1+2+3",$F4*$J$1/SUM($J$1:$P$1),IF($I4="GLD1+2",$F4*$J$1/SUM($J$1:$M$1),IF($I4="GLD1",$F4,0)))),0) -> 0 | L4: =IF($I4="GLD1+2+3+5+6",SUM($G4:$H4)*$J$1/SUM($J$1:$V$1),IF($I4="GLD1+2+3",SUM($G4:$H4)*$J$1/SUM($J$1:$P$1),IF($I4="GLD1+2+3",SUM($G4:$H4)*$J$1/SUM($J$1:$P$1),IF($I4="GLD1+2",SUM($G4:$H4)*$J$1/SUM($J$1:$M$1),IF($I4="GLD1",SUM($G4:$H4),0))))) -> 0 | M4: =IF(E4="HL",0,IF($I4="GLD1+2+3+5+6",$F4*$M$1/SUM($J$1:$V$1),IF($I4="GLD1+2+3",$F4*$M$1/SUM($J$1:$P$1),IF($I4="GLD1+2",$F4*$M$1/SUM($J$1:$M$1),IF($I4="GLD2",$F4,0))))) -> 3.030303 | N4: =IF(E4="HL",IF($I4="GLD1+2+3+5+6",$F4*$M$1/SUM($J$1:$V$1),IF($I4="GLD1+2+3",$F4*$M$1/SUM($J$1:$P$1),IF($I4="GLD1+2",$F4*$M$1/SUM($J$1:$M$1),IF($I4="GLD2",$F4,0)))),0) -> 0 | O4: =IF($I4="GLD1+2+3+5+6",SUM($G4:$H4)*$M$1/SUM($J$1:$V$1),IF($I4="GLD1+2+3",SUM($G4:$H4)*$M$1/SUM($J$1:$P$1),IF($I4="GLD1+2+3",SUM($G4:$H4)*$M$1/SUM($J$1:$P$1),IF($I4="GLD1+2",SUM($G4:$H4)*$M$1/SUM($J$1:$M$1),IF($I4="GLD2",SUM($G4:$H4),0))))) -> 0 | P4: =IF(E4="HL",0,IF($I4="GLD1+2+3+5+6",$F4*$P$1/SUM($J$1:$V$1),IF($I4="GLD3+5",$F4*$P$1/SUM($P$1:$S$1),IF($I4="GLD1+2",0,IF($I4="GLD3",$F4,0))))) -> 1.2121212 | Q4: =IF(E4="HL",IF($I4="GLD1+2+3+5+6",$F4*$P$1/SUM($J$1:$V$1),IF($I4="GLD3+5",$F4*$P$1/SUM($P$1:$S$1),IF($I4="GLD1+2",0,IF($I4="GLD3",$F4,0)))),0) -> 0 | R4: =IF($I4="GLD1+2+3+5+6",SUM($G4:$H4)*$P$1/SUM($J$1:$V$1),IF($I4="GLD3+5",SUM($G4:$H4)*$P$1/SUM($P$1:$S$1),IF($I4="GLD1+2",0,IF($I4="GLD3",SUM($G4:$H4),0)))) -> 0 | S4: =IF(E4="HL",0,IF($I4="GLD1+2+3+5+6",$F4*$S$1/SUM($J$1:$V$1),IF($I4="GLD3+5",$F4*$S$1/SUM($P$1:$S$1),IF($I4="GLD5",$F4,0)))) -> 1.5151515 | T4: =IF(E4="HL",IF($I4="GLD1+2+3+5+6",$F4*$S$1/SUM($J$1:$V$1),IF($I4="GLD3+5",$F4*$S$1/SUM($P$1:$S$1),IF($I4="GLD5",$F4,0))),0) -> 0 | U4: =IF($I4="GLD1+2+3+5+6",SUM($G4:$H4)*$S$1/SUM($J$1:$V$1),IF($I4="GLD3+5",SUM($G4:$H4)*$S$1/SUM($P$1:$S$1),IF($I4="GLD5",SUM($G4:$H4),0))) -> 0 | V4: =IF(E4="HL",0,IF($I4="GLD1+2+3+5+6",$F4*$V$1/SUM($J$1:$V$1),IF($I4="GLD6",$F4,0))) -> 1.5151515 | W4: =IF(E4="HL",IF($I4="GLD1+2+3+5+6",$F4*$V$1/SUM($J$1:$V$1),IF($I4="GLD6",$F4,0)),0) -> 0 | X4: =IF($I4="GLD1+2+3+5+6",SUM($G4:$H4)*$V$1/SUM($J$1:$V$1),IF($I4="GLD6",SUM($G4:$H4),0)) -> 0 | Y4: =IF(E4="HL",F4-(K4+N4+Q4+T4+W4),F4-(J4+M4+P4+S4+V4)) -> 0 | Z4: =IF(ABS(SUM(J4:X4)-(F4+G4+H4))>=1,"check","")
A5: =GLD!B24 -> Cleaning Cervice | B5: =IF(OR(A5=0,LEFT(A5,2)="Mr",LEFT(A5,2)="Ms",LEFT(A5,3)="Sub",LEFT(A5,5)="Grand",RIGHT(A5,3)="by,"),"",IF(ISERROR(MATCH(A5,'Dept (不許動)'!$S:$S,0)),"NO","")) | C5: =IF(A5=0,"",IF(ISNA(VLOOKUP(A5,'Dept (不許動)'!$S:$V,2,0)),"",VLOOKUP(A5,'Dept (不許動)'!$S:$V,2,0))) -> IDL | D5: =IF(A5=0,"",IF(ISNA(VLOOKUP(A5,'Dept (不許動)'!$S:$V,3,0)),"",VLOOKUP(A5,'Dept (不許動)'!$S:$V,3,0))) -> IDL others | E5: =IF(A5=0,"",IF(ISNA(VLOOKUP(A5,'Dept (不許動)'!$S:$V,4,0)),"",VLOOKUP(A5,'Dept (不許動)'!$S:$V,4,0))) -> 0 | F5: =GLD!$BC24 -> 8 | G5: =GLD!$AT24 -> 0 | H5: =GLD!$AV24 -> 0 | I5: =IF($D5="Embordiary","GLD6",IF(ISNA(VLOOKUP(A5,'GLD分攤(Chad)'!$B$2:$E$572,3,0)),"",(VLOOKUP(A5,'GLD分攤(Chad)'!$B$9:$E$572,3,0)))) -> GLD1 | J5: =IF(E5="HL",0,IF($I5="GLD1+2+3+5+6",$F5*$J$1/SUM($J$1:$V$1),IF($I5="GLD1+2+3",$F5*$J$1/SUM($J$1:$P$1),IF($I5="GLD1+2",$F5*$J$1/SUM($J$1:$M$1),IF($I5="GLD1",$F5,0))))) -> 8 | K5: =IF(E5="HL",IF($I5="GLD1+2+3+5+6",$F5*$J$1/SUM($J$1:$V$1),IF($I5="GLD1+2+3",$F5*$J$1/SUM($J$1:$P$1),IF($I5="GLD1+2",$F5*$J$1/SUM($J$1:$M$1),IF($I5="GLD1",$F5,0)))),0) -> 0 | L5: =IF($I5="GLD1+2+3+5+6",SUM($G5:$H5)*$J$1/SUM($J$1:$V$1),IF($I5="GLD1+2+3",SUM($G5:$H5)*$J$1/SUM($J$1:$P$1),IF($I5="GLD1+2+3",SUM($G5:$H5)*$J$1/SUM($J$1:$P$1),IF($I5="GLD1+2",SUM($G5:$H5)*$J$1/SUM($J$1:$M$1),IF($I5="GLD1",SUM($G5:$H5),0))))) -> 0 | M5: =IF(E5="HL",0,IF($I5="GLD1+2+3+5+6",$F5*$M$1/SUM($J$1:$V$1),IF($I5="GLD1+2+3",$F5*$M$1/SUM($J$1:$P$1),IF($I5="GLD1+2",$F5*$M$1/SUM($J$1:$M$1),IF($I5="GLD2",$F5,0))))) -> 0 | N5: =IF(E5="HL",IF($I5="GLD1+2+3+5+6",$F5*$M$1/SUM($J$1:$V$1),IF($I5="GLD1+2+3",$F5*$M$1/SUM($J$1:$P$1),IF($I5="GLD1+2",$F5*$M$1/SUM($J$1:$M$1),IF($I5="GLD2",$F5,0)))),0) -> 0 | O5: =IF($I5="GLD1+2+3+5+6",SUM($G5:$H5)*$M$1/SUM($J$1:$V$1),IF($I5="GLD1+2+3",SUM($G5:$H5)*$M$1/SUM($J$1:$P$1),IF($I5="GLD1+2+3",SUM($G5:$H5)*$M$1/SUM($J$1:$P$1),IF($I5="GLD1+2",SUM($G5:$H5)*$M$1/SUM($J$1:$M$1),IF($I5="GLD2",SUM($G5:$H5),0))))) -> 0 | P5: =IF(E5="HL",0,IF($I5="GLD1+2+3+5+6",$F5*$P$1/SUM($J$1:$V$1),IF($I5="GLD3+5",$F5*$P$1/SUM($P$1:$S$1),IF($I5="GLD1+2",0,IF($I5="GLD3",$F5,0))))) -> 0 | Q5: =IF(E5="HL",IF($I5="GLD1+2+3+5+6",$F5*$P$1/SUM($J$1:$V$1),IF($I5="GLD3+5",$F5*$P$1/SUM($P$1:$S$1),IF($I5="GLD1+2",0,IF($I5="GLD3",$F5,0)))),0) -> 0 | R5: =IF($I5="GLD1+2+3+5+6",SUM($G5:$H5)*$P$1/SUM($J$1:$V$1),IF($I5="GLD3+5",SUM($G5:$H5)*$P$1/SUM($P$1:$S$1),IF($I5="GLD1+2",0,IF($I5="GLD3",SUM($G5:$H5),0)))) -> 0 | S5: =IF(E5="HL",0,IF($I5="GLD1+2+3+5+6",$F5*$S$1/SUM($J$1:$V$1),IF($I5="GLD3+5",$F5*$S$1/SUM($P$1:$S$1),IF($I5="GLD5",$F5,0)))) -> 0 | T5: =IF(E5="HL",IF($I5="GLD1+2+3+5+6",$F5*$S$1/SUM($J$1:$V$1),IF($I5="GLD3+5",$F5*$S$1/SUM($P$1:$S$1),IF($I5="GLD5",$F5,0))),0) -> 0 | U5: =IF($I5="GLD1+2+3+5+6",SUM($G5:$H5)*$S$1/SUM($J$1:$V$1),IF($I5="GLD3+5",SUM($G5:$H5)*$S$1/SUM($P$1:$S$1),IF($I5="GLD5",SUM($G5:$H5),0))) -> 0 | V5: =IF(E5="HL",0,IF($I5="GLD1+2+3+5+6",$F5*$V$1/SUM($J$1:$V$1),IF($I5="GLD6",$F5,0))) -> 0 | W5: =IF(E5="HL",IF($I5="GLD1+2+3+5+6",$F5*$V$1/SUM($J$1:$V$1),IF($I5="GLD6",$F5,0)),0) -> 0 | X5: =IF($I5="GLD1+2+3+5+6",SUM($G5:$H5)*$V$1/SUM($J$1:$V$1),IF($I5="GLD6",SUM($G5:$H5),0)) -> 0 | Y5: =IF(E5="HL",F5-(K5+N5+Q5+T5+W5),F5-(J5+M5+P5+S5+V5)) -> 0 | Z5: =IF(ABS(SUM(J5:X5)-(F5+G5+H5))>=1,"check","")
A6: =GLD!B25 -> Cleaning Cervice - 2 | B6: =IF(OR(A6=0,LEFT(A6,2)="Mr",LEFT(A6,2)="Ms",LEFT(A6,3)="Sub",LEFT(A6,5)="Grand",RIGHT(A6,3)="by,"),"",IF(ISERROR(MATCH(A6,'Dept (不許動)'!$S:$S,0)),"NO","")) | C6: =IF(A6=0,"",IF(ISNA(VLOOKUP(A6,'Dept (不許動)'!$S:$V,2,0)),"",VLOOKUP(A6,'Dept (不許動)'!$S:$V,2,0))) -> IDL | D6: =IF(A6=0,"",IF(ISNA(VLOOKUP(A6,'Dept (不許動)'!$S:$V,3,0)),"",VLOOKUP(A6,'Dept (不許動)'!$S:$V,3,0))) -> IDL others | E6: =IF(A6=0,"",IF(ISNA(VLOOKUP(A6,'Dept (不許動)'!$S:$V,4,0)),"",VLOOKUP(A6,'Dept (不許動)'!$S:$V,4,0))) -> 0 | F6: =GLD!$BC25 -> 5 | G6: =GLD!$AT25 -> 0 | H6: =GLD!$AV25 -> 0 | I6: =IF($D6="Embordiary","GLD6",IF(ISNA(VLOOKUP(A6,'GLD分攤(Chad)'!$B$2:$E$572,3,0)),"",(VLOOKUP(A6,'GLD分攤(Chad)'!$B$9:$E$572,3,0)))) -> GLD2 | J6: =IF(E6="HL",0,IF($I6="GLD1+2+3+5+6",$F6*$J$1/SUM($J$1:$V$1),IF($I6="GLD1+2+3",$F6*$J$1/SUM($J$1:$P$1),IF($I6="GLD1+2",$F6*$J$1/SUM($J$1:$M$1),IF($I6="GLD1",$F6,0))))) -> 0 | K6: =IF(E6="HL",IF($I6="GLD1+2+3+5+6",$F6*$J$1/SUM($J$1:$V$1),IF($I6="GLD1+2+3",$F6*$J$1/SUM($J$1:$P$1),IF($I6="GLD1+2",$F6*$J$1/SUM($J$1:$M$1),IF($I6="GLD1",$F6,0)))),0) -> 0 | L6: =IF($I6="GLD1+2+3+5+6",SUM($G6:$H6)*$J$1/SUM($J$1:$V$1),IF($I6="GLD1+2+3",SUM($G6:$H6)*$J$1/SUM($J$1:$P$1),IF($I6="GLD1+2+3",SUM($G6:$H6)*$J$1/SUM($J$1:$P$1),IF($I6="GLD1+2",SUM($G6:$H6)*$J$1/SUM($J$1:$M$1),IF($I6="GLD1",SUM($G6:$H6),0))))) -> 0 | M6: =IF(E6="HL",0,IF($I6="GLD1+2+3+5+6",$F6*$M$1/SUM($J$1:$V$1),IF($I6="GLD1+2+3",$F6*$M$1/SUM($J$1:$P$1),IF($I6="GLD1+2",$F6*$M$1/SUM($J$1:$M$1),IF($I6="GLD2",$F6,0))))) -> 5 | N6: =IF(E6="HL",IF($I6="GLD1+2+3+5+6",$F6*$M$1/SUM($J$1:$V$1),IF($I6="GLD1+2+3",$F6*$M$1/SUM($J$1:$P$1),IF($I6="GLD1+2",$F6*$M$1/SUM($J$1:$M$1),IF($I6="GLD2",$F6,0)))),0) -> 0 | O6: =IF($I6="GLD1+2+3+5+6",SUM($G6:$H6)*$M$1/SUM($J$1:$V$1),IF($I6="GLD1+2+3",SUM($G6:$H6)*$M$1/SUM($J$1:$P$1),IF($I6="GLD1+2+3",SUM($G6:$H6)*$M$1/SUM($J$1:$P$1),IF($I6="GLD1+2",SUM($G6:$H6)*$M$1/SUM($J$1:$M$1),IF($I6="GLD2",SUM($G6:$H6),0))))) -> 0 | P6: =IF(E6="HL",0,IF($I6="GLD1+2+3+5+6",$F6*$P$1/SUM($J$1:$V$1),IF($I6="GLD3+5",$F6*$P$1/SUM($P$1:$S$1),IF($I6="GLD1+2",0,IF($I6="GLD3",$F6,0))))) -> 0 | Q6: =IF(E6="HL",IF($I6="GLD1+2+3+5+6",$F6*$P$1/SUM($J$1:$V$1),IF($I6="GLD3+5",$F6*$P$1/SUM($P$1:$S$1),IF($I6="GLD1+2",0,IF($I6="GLD3",$F6,0)))),0) -> 0 | R6: =IF($I6="GLD1+2+3+5+6",SUM($G6:$H6)*$P$1/SUM($J$1:$V$1),IF($I6="GLD3+5",SUM($G6:$H6)*$P$1/SUM($P$1:$S$1),IF($I6="GLD1+2",0,IF($I6="GLD3",SUM($G6:$H6),0)))) -> 0 | S6: =IF(E6="HL",0,IF($I6="GLD1+2+3+5+6",$F6*$S$1/SUM($J$1:$V$1),IF($I6="GLD3+5",$F6*$S$1/SUM($P$1:$S$1),IF($I6="GLD5",$F6,0)))) -> 0 | T6: =IF(E6="HL",IF($I6="GLD1+2+3+5+6",$F6*$S$1/SUM($J$1:$V$1),IF($I6="GLD3+5",$F6*$S$1/SUM($P$1:$S$1),IF($I6="GLD5",$F6,0))),0) -> 0 | U6: =IF($I6="GLD1+2+3+5+6",SUM($G6:$H6)*$S$1/SUM($J$1:$V$1),IF($I6="GLD3+5",SUM($G6:$H6)*$S$1/SUM($P$1:$S$1),IF($I6="GLD5",SUM($G6:$H6),0))) -> 0 | V6: =IF(E6="HL",0,IF($I6="GLD1+2+3+5+6",$F6*$V$1/SUM($J$1:$V$1),IF($I6="GLD6",$F6,0))) -> 0 | W6: =IF(E6="HL",IF($I6="GLD1+2+3+5+6",$F6*$V$1/SUM($J$1:$V$1),IF($I6="GLD6",$F6,0)),0) -> 0 | X6: =IF($I6="GLD1+2+3+5+6",SUM($G6:$H6)*$V$1/SUM($J$1:$V$1),IF($I6="GLD6",SUM($G6:$H6),0)) -> 0 | Y6: =IF(E6="HL",F6-(K6+N6+Q6+T6+W6),F6-(J6+M6+P6+S6+V6)) -> 0 | Z6: =IF(ABS(SUM(J6:X6)-(F6+G6+H6))>=1,"check","")
A7: =GLD!B26 -> Cleaning Cervice - 3 | B7: =IF(OR(A7=0,LEFT(A7,2)="Mr",LEFT(A7,2)="Ms",LEFT(A7,3)="Sub",LEFT(A7,5)="Grand",RIGHT(A7,3)="by,"),"",IF(ISERROR(MATCH(A7,'Dept (不許動)'!$S:$S,0)),"NO","")) | C7: =IF(A7=0,"",IF(ISNA(VLOOKUP(A7,'Dept (不許動)'!$S:$V,2,0)),"",VLOOKUP(A7,'Dept (不許動)'!$S:$V,2,0))) -> IDL | D7: =IF(A7=0,"",IF(ISNA(VLOOKUP(A7,'Dept (不許動)'!$S:$V,3,0)),"",VLOOKUP(A7,'Dept (不許動)'!$S:$V,3,0))) -> IDL others | E7: =IF(A7=0,"",IF(ISNA(VLOOKUP(A7,'Dept (不許動)'!$S:$V,4,0)),"",VLOOKUP(A7,'Dept (不許動)'!$S:$V,4,0))) -> 0 | F7: =GLD!$BC26 -> 4 | G7: =GLD!$AT26 -> 0 | H7: =GLD!$AV26 -> 0 | I7: =IF($D7="Embordiary","GLD6",IF(ISNA(VLOOKUP(A7,'GLD分攤(Chad)'!$B$2:$E$572,3,0)),"",(VLOOKUP(A7,'GLD分攤(Chad)'!$B$9:$E$572,3,0)))) -> GLD3 | J7: =IF(E7="HL",0,IF($I7="GLD1+2+3+5+6",$F7*$J$1/SUM($J$1:$V$1),IF($I7="GLD1+2+3",$F7*$J$1/SUM($J$1:$P$1),IF($I7="GLD1+2",$F7*$J$1/SUM($J$1:$M$1),IF($I7="GLD1",$F7,0))))) -> 0 | K7: =IF(E7="HL",IF($I7="GLD1+2+3+5+6",$F7*$J$1/SUM($J$1:$V$1),IF($I7="GLD1+2+3",$F7*$J$1/SUM($J$1:$P$1),IF($I7="GLD1+2",$F7*$J$1/SUM($J$1:$M$1),IF($I7="GLD1",$F7,0)))),0) -> 0 | L7: =IF($I7="GLD1+2+3+5+6",SUM($G7:$H7)*$J$1/SUM($J$1:$V$1),IF($I7="GLD1+2+3",SUM($G7:$H7)*$J$1/SUM($J$1:$P$1),IF($I7="GLD1+2+3",SUM($G7:$H7)*$J$1/SUM($J$1:$P$1),IF($I7="GLD1+2",SUM($G7:$H7)*$J$1/SUM($J$1:$M$1),IF($I7="GLD1",SUM($G7:$H7),0))))) -> 0 | M7: =IF(E7="HL",0,IF($I7="GLD1+2+3+5+6",$F7*$M$1/SUM($J$1:$V$1),IF($I7="GLD1+2+3",$F7*$M$1/SUM($J$1:$P$1),IF($I7="GLD1+2",$F7*$M$1/SUM($J$1:$M$1),IF($I7="GLD2",$F7,0))))) -> 0 | N7: =IF(E7="HL",IF($I7="GLD1+2+3+5+6",$F7*$M$1/SUM($J$1:$V$1),IF($I7="GLD1+2+3",$F7*$M$1/SUM($J$1:$P$1),IF($I7="GLD1+2",$F7*$M$1/SUM($J$1:$M$1),IF($I7="GLD2",$F7,0)))),0) -> 0 | O7: =IF($I7="GLD1+2+3+5+6",SUM($G7:$H7)*$M$1/SUM($J$1:$V$1),IF($I7="GLD1+2+3",SUM($G7:$H7)*$M$1/SUM($J$1:$P$1),IF($I7="GLD1+2+3",SUM($G7:$H7)*$M$1/SUM($J$1:$P$1),IF($I7="GLD1+2",SUM($G7:$H7)*$M$1/SUM($J$1:$M$1),IF($I7="GLD2",SUM($G7:$H7),0))))) -> 0 | P7: =IF(E7="HL",0,IF($I7="GLD1+2+3+5+6",$F7*$P$1/SUM($J$1:$V$1),IF($I7="GLD3+5",$F7*$P$1/SUM($P$1:$S$1),IF($I7="GLD1+2",0,IF($I7="GLD3",$F7,0))))) -> 4 | Q7: =IF(E7="HL",IF($I7="GLD1+2+3+5+6",$F7*$P$1/SUM($J$1:$V$1),IF($I7="GLD3+5",$F7*$P$1/SUM($P$1:$S$1),IF($I7="GLD1+2",0,IF($I7="GLD3",$F7,0)))),0) -> 0 | R7: =IF($I7="GLD1+2+3+5+6",SUM($G7:$H7)*$P$1/SUM($J$1:$V$1),IF($I7="GLD3+5",SUM($G7:$H7)*$P$1/SUM($P$1:$S$1),IF($I7="GLD1+2",0,IF($I7="GLD3",SUM($G7:$H7),0)))) -> 0 | S7: =IF(E7="HL",0,IF($I7="GLD1+2+3+5+6",$F7*$S$1/SUM($J$1:$V$1),IF($I7="GLD3+5",$F7*$S$1/SUM($P$1:$S$1),IF($I7="GLD5",$F7,0)))) -> 0 | T7: =IF(E7="HL",IF($I7="GLD1+2+3+5+6",$F7*$S$1/SUM($J$1:$V$1),IF($I7="GLD3+5",$F7*$S$1/SUM($P$1:$S$1),IF($I7="GLD5",$F7,0))),0) -> 0 | U7: =IF($I7="GLD1+2+3+5+6",SUM($G7:$H7)*$S$1/SUM($J$1:$V$1),IF($I7="GLD3+5",SUM($G7:$H7)*$S$1/SUM($P$1:$S$1),IF($I7="GLD5",SUM($G7:$H7),0))) -> 0 | V7: =IF(E7="HL",0,IF($I7="GLD1+2+3+5+6",$F7*$V$1/SUM($J$1:$V$1),IF($I7="GLD6",$F7,0))) -> 0 | W7: =IF(E7="HL",IF($I7="GLD1+2+3+5+6",$F7*$V$1/SUM($J$1:$V$1),IF($I7="GLD6",$F7,0)),0) -> 0 | X7: =IF($I7="GLD1+2+3+5+6",SUM($G7:$H7)*$V$1/SUM($J$1:$V$1),IF($I7="GLD6",SUM($G7:$H7),0)) -> 0 | Y7: =IF(E7="HL",F7-(K7+N7+Q7+T7+W7),F7-(J7+M7+P7+S7+V7)) -> 0 | Z7: =IF(ABS(SUM(J7:X7)-(F7+G7+H7))>=1,"check","")
A8: =GLD!B27 -> Cleaning Cervice - 5 | B8: =IF(OR(A8=0,LEFT(A8,2)="Mr",LEFT(A8,2)="Ms",LEFT(A8,3)="Sub",LEFT(A8,5)="Grand",RIGHT(A8,3)="by,"),"",IF(ISERROR(MATCH(A8,'Dept (不許動)'!$S:$S,0)),"NO","")) | C8: =IF(A8=0,"",IF(ISNA(VLOOKUP(A8,'Dept (不許動)'!$S:$V,2,0)),"",VLOOKUP(A8,'Dept (不許動)'!$S:$V,2,0))) -> IDL | D8: =IF(A8=0,"",IF(ISNA(VLOOKUP(A8,'Dept (不許動)'!$S:$V,3,0)),"",VLOOKUP(A8,'Dept (不許動)'!$S:$V,3,0))) -> IDL others | E8: =IF(A8=0,"",IF(ISNA(VLOOKUP(A8,'Dept (不許動)'!$S:$V,4,0)),"",VLOOKUP(A8,'Dept (不許動)'!$S:$V,4,0))) -> 0 | F8: =GLD!$BC27 -> 6 | G8: =GLD!$AT27 -> 0 | H8: =GLD!$AV27 -> 0 | I8: =IF($D8="Embordiary","GLD6",IF(ISNA(VLOOKUP(A8,'GLD分攤(Chad)'!$B$2:$E$572,3,0)),"",(VLOOKUP(A8,'GLD分攤(Chad)'!$B$9:$E$572,3,0)))) -> GLD5 | J8: =IF(E8="HL",0,IF($I8="GLD1+2+3+5+6",$F8*$J$1/SUM($J$1:$V$1),IF($I8="GLD1+2+3",$F8*$J$1/SUM($J$1:$P$1),IF($I8="GLD1+2",$F8*$J$1/SUM($J$1:$M$1),IF($I8="GLD1",$F8,0))))) -> 0 | K8: =IF(E8="HL",IF($I8="GLD1+2+3+5+6",$F8*$J$1/SUM($J$1:$V$1),IF($I8="GLD1+2+3",$F8*$J$1/SUM($J$1:$P$1),IF($I8="GLD1+2",$F8*$J$1/SUM($J$1:$M$1),IF($I8="GLD1",$F8,0)))),0) -> 0 | L8: =IF($I8="GLD1+2+3+5+6",SUM($G8:$H8)*$J$1/SUM($J$1:$V$1),IF($I8="GLD1+2+3",SUM($G8:$H8)*$J$1/SUM($J$1:$P$1),IF($I8="GLD1+2+3",SUM($G8:$H8)*$J$1/SUM($J$1:$P$1),IF($I8="GLD1+2",SUM($G8:$H8)*$J$1/SUM($J$1:$M$1),IF($I8="GLD1",SUM($G8:$H8),0))))) -> 0 | M8: =IF(E8="HL",0,IF($I8="GLD1+2+3+5+6",$F8*$M$1/SUM($J$1:$V$1),IF($I8="GLD1+2+3",$F8*$M$1/SUM($J$1:$P$1),IF($I8="GLD1+2",$F8*$M$1/SUM($J$1:$M$1),IF($I8="GLD2",$F8,0))))) -> 0 | N8: =IF(E8="HL",IF($I8="GLD1+2+3+5+6",$F8*$M$1/SUM($J$1:$V$1),IF($I8="GLD1+2+3",$F8*$M$1/SUM($J$1:$P$1),IF($I8="GLD1+2",$F8*$M$1/SUM($J$1:$M$1),IF($I8="GLD2",$F8,0)))),0) -> 0 | O8: =IF($I8="GLD1+2+3+5+6",SUM($G8:$H8)*$M$1/SUM($J$1:$V$1),IF($I8="GLD1+2+3",SUM($G8:$H8)*$M$1/SUM($J$1:$P$1),IF($I8="GLD1+2+3",SUM($G8:$H8)*$M$1/SUM($J$1:$P$1),IF($I8="GLD1+2",SUM($G8:$H8)*$M$1/SUM($J$1:$M$1),IF($I8="GLD2",SUM($G8:$H8),0))))) -> 0 | P8: =IF(E8="HL",0,IF($I8="GLD1+2+3+5+6",$F8*$P$1/SUM($J$1:$V$1),IF($I8="GLD3+5",$F8*$P$1/SUM($P$1:$S$1),IF($I8="GLD1+2",0,IF($I8="GLD3",$F8,0))))) -> 0 | Q8: =IF(E8="HL",IF($I8="GLD1+2+3+5+6",$F8*$P$1/SUM($J$1:$V$1),IF($I8="GLD3+5",$F8*$P$1/SUM($P$1:$S$1),IF($I8="GLD1+2",0,IF($I8="GLD3",$F8,0)))),0) -> 0 | R8: =IF($I8="GLD1+2+3+5+6",SUM($G8:$H8)*$P$1/SUM($J$1:$V$1),IF($I8="GLD3+5",SUM($G8:$H8)*$P$1/SUM($P$1:$S$1),IF($I8="GLD1+2",0,IF($I8="GLD3",SUM($G8:$H8),0)))) -> 0 | S8: =IF(E8="HL",0,IF($I8="GLD1+2+3+5+6",$F8*$S$1/SUM($J$1:$V$1),IF($I8="GLD3+5",$F8*$S$1/SUM($P$1:$S$1),IF($I8="GLD5",$F8,0)))) -> 6 | T8: =IF(E8="HL",IF($I8="GLD1+2+3+5+6",$F8*$S$1/SUM($J$1:$V$1),IF($I8="GLD3+5",$F8*$S$1/SUM($P$1:$S$1),IF($I8="GLD5",$F8,0))),0) -> 0 | U8: =IF($I8="GLD1+2+3+5+6",SUM($G8:$H8)*$S$1/SUM($J$1:$V$1),IF($I8="GLD3+5",SUM($G8:$H8)*$S$1/SUM($P$1:$S$1),IF($I8="GLD5",SUM($G8:$H8),0))) -> 0 | V8: =IF(E8="HL",0,IF($I8="GLD1+2+3+5+6",$F8*$V$1/SUM($J$1:$V$1),IF($I8="GLD6",$F8,0))) -> 0 | W8: =IF(E8="HL",IF($I8="GLD1+2+3+5+6",$F8*$V$1/SUM($J$1:$V$1),IF($I8="GLD6",$F8,0)),0) -> 0 | X8: =IF($I8="GLD1+2+3+5+6",SUM($G8:$H8)*$V$1/SUM($J$1:$V$1),IF($I8="GLD6",SUM($G8:$H8),0)) -> 0 | Y8: =IF(E8="HL",F8-(K8+N8+Q8+T8+W8),F8-(J8+M8+P8+S8+V8)) -> 0 | Z8: =IF(ABS(SUM(J8:X8)-(F8+G8+H8))>=1,"check","")
A9: =GLD!B28 -> Cleaning Cervice - 6 | B9: =IF(OR(A9=0,LEFT(A9,2)="Mr",LEFT(A9,2)="Ms",LEFT(A9,3)="Sub",LEFT(A9,5)="Grand",RIGHT(A9,3)="by,"),"",IF(ISERROR(MATCH(A9,'Dept (不許動)'!$S:$S,0)),"NO","")) | C9: =IF(A9=0,"",IF(ISNA(VLOOKUP(A9,'Dept (不許動)'!$S:$V,2,0)),"",VLOOKUP(A9,'Dept (不許動)'!$S:$V,2,0))) -> IDL | D9: =IF(A9=0,"",IF(ISNA(VLOOKUP(A9,'Dept (不許動)'!$S:$V,3,0)),"",VLOOKUP(A9,'Dept (不許動)'!$S:$V,3,0))) -> IDL others | E9: =IF(A9=0,"",IF(ISNA(VLOOKUP(A9,'Dept (不許動)'!$S:$V,4,0)),"",VLOOKUP(A9,'Dept (不許動)'!$S:$V,4,0))) -> 0 | F9: =GLD!$BC28 -> 4 | G9: =GLD!$AT28 -> 0 | H9: =GLD!$AV28 -> 0 | I9: =IF($D9="Embordiary","GLD6",IF(ISNA(VLOOKUP(A9,'GLD分攤(Chad)'!$B$2:$E$572,3,0)),"",(VLOOKUP(A9,'GLD分攤(Chad)'!$B$9:$E$572,3,0)))) -> GLD6 | J9: =IF(E9="HL",0,IF($I9="GLD1+2+3+5+6",$F9*$J$1/SUM($J$1:$V$1),IF($I9="GLD1+2+3",$F9*$J$1/SUM($J$1:$P$1),IF($I9="GLD1+2",$F9*$J$1/SUM($J$1:$M$1),IF($I9="GLD1",$F9,0))))) -> 0 | K9: =IF(E9="HL",IF($I9="GLD1+2+3+5+6",$F9*$J$1/SUM($J$1:$V$1),IF($I9="GLD1+2+3",$F9*$J$1/SUM($J$1:$P$1),IF($I9="GLD1+2",$F9*$J$1/SUM($J$1:$M$1),IF($I9="GLD1",$F9,0)))),0) -> 0 | L9: =IF($I9="GLD1+2+3+5+6",SUM($G9:$H9)*$J$1/SUM($J$1:$V$1),IF($I9="GLD1+2+3",SUM($G9:$H9)*$J$1/SUM($J$1:$P$1),IF($I9="GLD1+2+3",SUM($G9:$H9)*$J$1/SUM($J$1:$P$1),IF($I9="GLD1+2",SUM($G9:$H9)*$J$1/SUM($J$1:$M$1),IF($I9="GLD1",SUM($G9:$H9),0))))) -> 0 | M9: =IF(E9="HL",0,IF($I9="GLD1+2+3+5+6",$F9*$M$1/SUM($J$1:$V$1),IF($I9="GLD1+2+3",$F9*$M$1/SUM($J$1:$P$1),IF($I9="GLD1+2",$F9*$M$1/SUM($J$1:$M$1),IF($I9="GLD2",$F9,0))))) -> 0 | N9: =IF(E9="HL",IF($I9="GLD1+2+3+5+6",$F9*$M$1/SUM($J$1:$V$1),IF($I9="GLD1+2+3",$F9*$M$1/SUM($J$1:$P$1),IF($I9="GLD1+2",$F9*$M$1/SUM($J$1:$M$1),IF($I9="GLD2",$F9,0)))),0) -> 0 | O9: =IF($I9="GLD1+2+3+5+6",SUM($G9:$H9)*$M$1/SUM($J$1:$V$1),IF($I9="GLD1+2+3",SUM($G9:$H9)*$M$1/SUM($J$1:$P$1),IF($I9="GLD1+2+3",SUM($G9:$H9)*$M$1/SUM($J$1:$P$1),IF($I9="GLD1+2",SUM($G9:$H9)*$M$1/SUM($J$1:$M$1),IF($I9="GLD2",SUM($G9:$H9),0))))) -> 0 | P9: =IF(E9="HL",0,IF($I9="GLD1+2+3+5+6",$F9*$P$1/SUM($J$1:$V$1),IF($I9="GLD3+5",$F9*$P$1/SUM($P$1:$S$1),IF($I9="GLD1+2",0,IF($I9="GLD3",$F9,0))))) -> 0 | Q9: =IF(E9="HL",IF($I9="GLD1+2+3+5+6",$F9*$P$1/SUM($J$1:$V$1),IF($I9="GLD3+5",$F9*$P$1/SUM($P$1:$S$1),IF($I9="GLD1+2",0,IF($I9="GLD3",$F9,0)))),0) -> 0 | R9: =IF($I9="GLD1+2+3+5+6",SUM($G9:$H9)*$P$1/SUM($J$1:$V$1),IF($I9="GLD3+5",SUM($G9:$H9)*$P$1/SUM($P$1:$S$1),IF($I9="GLD1+2",0,IF($I9="GLD3",SUM($G9:$H9),0)))) -> 0 | S9: =IF(E9="HL",0,IF($I9="GLD1+2+3+5+6",$F9*$S$1/SUM($J$1:$V$1),IF($I9="GLD3+5",$F9*$S$1/SUM($P$1:$S$1),IF($I9="GLD5",$F9,0)))) -> 0 | T9: =IF(E9="HL",IF($I9="GLD1+2+3+5+6",$F9*$S$1/SUM($J$1:$V$1),IF($I9="GLD3+5",$F9*$S$1/SUM($P$1:$S$1),IF($I9="GLD5",$F9,0))),0) -> 0 | U9: =IF($I9="GLD1+2+3+5+6",SUM($G9:$H9)*$S$1/SUM($J$1:$V$1),IF($I9="GLD3+5",SUM($G9:$H9)*$S$1/SUM($P$1:$S$1),IF($I9="GLD5",SUM($G9:$H9),0))) -> 0 | V9: =IF(E9="HL",0,IF($I9="GLD1+2+3+5+6",$F9*$V$1/SUM($J$1:$V$1),IF($I9="GLD6",$F9,0))) -> 4 | W9: =IF(E9="HL",IF($I9="GLD1+2+3+5+6",$F9*$V$1/SUM($J$1:$V$1),IF($I9="GLD6",$F9,0)),0) -> 0 | X9: =IF($I9="GLD1+2+3+5+6",SUM($G9:$H9)*$V$1/SUM($J$1:$V$1),IF($I9="GLD6",SUM($G9:$H9),0)) -> 0 | Y9: =IF(E9="HL",F9-(K9+N9+Q9+T9+W9),F9-(J9+M9+P9+S9+V9)) -> 0 | Z9: =IF(ABS(SUM(J9:X9)-(F9+G9+H9))>=1,"check","")
A10: =GLD!B29 -> HRD(Personnel/Payroll) | B10: =IF(OR(A10=0,LEFT(A10,2)="Mr",LEFT(A10,2)="Ms",LEFT(A10,3)="Sub",LEFT(A10,5)="Grand",RIGHT(A10,3)="by,"),"",IF(ISERROR(MATCH(A10,'Dept (不許動)'!$S:$S,0)),"NO","")) | C10: =IF(A10=0,"",IF(ISNA(VLOOKUP(A10,'Dept (不許動)'!$S:$V,2,0)),"",VLOOKUP(A10,'Dept (不許動)'!$S:$V,2,0))) -> IDL | D10: =IF(A10=0,"",IF(ISNA(VLOOKUP(A10,'Dept (不許動)'!$S:$V,3,0)),"",VLOOKUP(A10,'Dept (不許動)'!$S:$V,3,0))) -> IDL others | E10: =IF(A10=0,"",IF(ISNA(VLOOKUP(A10,'Dept (不許動)'!$S:$V,4,0)),"",VLOOKUP(A10,'Dept (不許動)'!$S:$V,4,0))) -> 0 | F10: =GLD!$BC29 -> 12 | G10: =GLD!$AT29 -> 0 | H10: =GLD!$AV29 -> 0 | I10: =IF($D10="Embordiary","GLD6",IF(ISNA(VLOOKUP(A10,'GLD分攤(Chad)'!$B$2:$E$572,3,0)),"",(VLOOKUP(A10,'GLD分攤(Chad)'!$B$9:$E$572,3,0)))) -> GLD1+2+3+5+6 | J10: =IF(E10="HL",0,IF($I10="GLD1+2+3+5+6",$F10*$J$1/SUM($J$1:$V$1),IF($I10="GLD1+2+3",$F10*$J$1/SUM($J$1:$P$1),IF($I10="GLD1+2",$F10*$J$1/SUM($J$1:$M$1),IF($I10="GLD1",$F10,0))))) -> 3.2727273 | K10: =IF(E10="HL",IF($I10="GLD1+2+3+5+6",$F10*$J$1/SUM($J$1:$V$1),IF($I10="GLD1+2+3",$F10*$J$1/SUM($J$1:$P$1),IF($I10="GLD1+2",$F10*$J$1/SUM($J$1:$M$1),IF($I10="GLD1",$F10,0)))),0) -> 0 | L10: =IF($I10="GLD1+2+3+5+6",SUM($G10:$H10)*$J$1/SUM($J$1:$V$1),IF($I10="GLD1+2+3",SUM($G10:$H10)*$J$1/SUM($J$1:$P$1),IF($I10="GLD1+2+3",SUM($G10:$H10)*$J$1/SUM($J$1:$P$1),IF($I10="GLD1+2",SUM($G10:$H10)*$J$1/SUM($J$1:$M$1),IF($I10="GLD1",SUM($G10:$H10),0))))) -> 0 | M10: =IF(E10="HL",0,IF($I10="GLD1+2+3+5+6",$F10*$M$1/SUM($J$1:$V$1),IF($I10="GLD1+2+3",$F10*$M$1/SUM($J$1:$P$1),IF($I10="GLD1+2",$F10*$M$1/SUM($J$1:$M$1),IF($I10="GLD2",$F10,0))))) -> 3.6363636 | N10: =IF(E10="HL",IF($I10="GLD1+2+3+5+6",$F10*$M$1/SUM($J$1:$V$1),IF($I10="GLD1+2+3",$F10*$M$1/SUM($J$1:$P$1),IF($I10="GLD1+2",$F10*$M$1/SUM($J$1:$M$1),IF($I10="GLD2",$F10,0)))),0) -> 0 | O10: =IF($I10="GLD1+2+3+5+6",SUM($G10:$H10)*$M$1/SUM($J$1:$V$1),IF($I10="GLD1+2+3",SUM($G10:$H10)*$M$1/SUM($J$1:$P$1),IF($I10="GLD1+2+3",SUM($G10:$H10)*$M$1/SUM($J$1:$P$1),IF($I10="GLD1+2",SUM($G10:$H10)*$M$1/SUM($J$1:$M$1),IF($I10="GLD2",SUM($G10:$H10),0))))) -> 0 | P10: =IF(E10="HL",0,IF($I10="GLD1+2+3+5+6",$F10*$P$1/SUM($J$1:$V$1),IF($I10="GLD3+5",$F10*$P$1/SUM($P$1:$S$1),IF($I10="GLD1+2",0,IF($I10="GLD3",$F10,0))))) -> 1.4545455 | Q10: =IF(E10="HL",IF($I10="GLD1+2+3+5+6",$F10*$P$1/SUM($J$1:$V$1),IF($I10="GLD3+5",$F10*$P$1/SUM($P$1:$S$1),IF($I10="GLD1+2",0,IF($I10="GLD3",$F10,0)))),0) -> 0 | R10: =IF($I10="GLD1+2+3+5+6",SUM($G10:$H10)*$P$1/SUM($J$1:$V$1),IF($I10="GLD3+5",SUM($G10:$H10)*$P$1/SUM($P$1:$S$1),IF($I10="GLD1+2",0,IF($I10="GLD3",SUM($G10:$H10),0)))) -> 0 | S10: =IF(E10="HL",0,IF($I10="GLD1+2+3+5+6",$F10*$S$1/SUM($J$1:$V$1),IF($I10="GLD3+5",$F10*$S$1/SUM($P$1:$S$1),IF($I10="GLD5",$F10,0)))) -> 1.8181818 | T10: =IF(E10="HL",IF($I10="GLD1+2+3+5+6",$F10*$S$1/SUM($J$1:$V$1),IF($I10="GLD3+5",$F10*$S$1/SUM($P$1:$S$1),IF($I10="GLD5",$F10,0))),0) -> 0 | U10: =IF($I10="GLD1+2+3+5+6",SUM($G10:$H10)*$S$1/SUM($J$1:$V$1),IF($I10="GLD3+5",SUM($G10:$H10)*$S$1/SUM($P$1:$S$1),IF($I10="GLD5",SUM($G10:$H10),0))) -> 0 | V10: =IF(E10="HL",0,IF($I10="GLD1+2+3+5+6",$F10*$V$1/SUM($J$1:$V$1),IF($I10="GLD6",$F10,0))) -> 1.8181818 | W10: =IF(E10="HL",IF($I10="GLD1+2+3+5+6",$F10*$V$1/SUM($J$1:$V$1),IF($I10="GLD6",$F10,0)),0) -> 0 | X10: =IF($I10="GLD1+2+3+5+6",SUM($G10:$H10)*$V$1/SUM($J$1:$V$1),IF($I10="GLD6",SUM($G10:$H10),0)) -> 0 | Y10: =IF(E10="HL",F10-(K10+N10+Q10+T10+W10),F10-(J10+M10+P10+S10+V10)) -> 0 | Z10: =IF(ABS(SUM(J10:X10)-(F10+G10+H10))>=1,"check","")
